Workbook

Sheet SV777 - ХК3.1 (SV005)
E2: Стойка | M2: XK | N2: 3.1
E3: Контроллер SV 777 | M3: № | N3: =N2&".1" -> 3.1.1
E4: Плата SV 005 | M4: № | N4: 1
E5: Наименование плинтодержателя | M5: ХВ1 | N5: ="-"&N2&".1" -> -3.1.1
E6: Номер плинта | M6: № | N6: 1
E7: СКУД | M7: № | N7: 3.1
B10: к SV 005 разъемы R1 и D1
B12: 0 | D12: 1 | E12: 1 | F12: 2 | G12: 2 | H12: 3 | I12: 3 | J12: 4 | K12: 4 | L12: 5 | N12: 6 | O12: 1 | P12: 7 | Q12: 2 | R12: 8 | S12: 3 | T12: 9 | U12: 4
B16: =IF(Q16>1,"Считыватель вх",IF(F16<1,"","Считыватель вх")) -> Считыватель вх | F16: 1 | J16: =IF(Q16>1,"замок",IF(K16<1,"",IF(F16<1,"замок пож.дв.","замок"))) -> замок | K16: 10 | L16: сирена | M16: к ХВ20 | N16: геркон | O16: 7 | P16: кн. Вых | R16: оборудование\ кабель
B17: пом. 305 | R17: *(помещение№)
E21: Стойка | M21: XK | N21: =N2 -> 3.1
E22: Контроллер SV 777 | M22: № | N22: =N2&".1" -> 3.1.1
E23: Плата SV 005 | M23: № | N23: =N4 -> 1
E24: Наименование плинтодержателя | M24: ХВ1 | N24: =N5 -> -3.1.1
E25: Номер плинта | M25: № | N25: =N6+1 -> 2
E26: СКУД | M26: № | N26: 3.1
B29: к SV 005 разъемы R2 и D2
B31: 0 | D31: 1 | E31: 1 | F31: 2 | G31: 2 | H31: 3 | I31: 3 | J31: 4 | K31: 4 | L31: 5 | N31: 6 | O31: 1 | P31: 7 | Q31: 2 | R31: 8 | S31: 3 | T31: 9 | U31: 4
B35: =IF(Q35>1,"Считыватель вх",IF(F35<1,"","Считыватель вых")) -> Считыватель вых | F35: 4 | J35: =IF(Q35>1,"замок",IF(K35>1,"замок пож.дв.","замок")) -> замок | L35: сирена | M35: к ХВ20 | N35: геркон | P35: кн. Вых | R35: оборудование\ кабель
B36: =IF(B35="Считыватель вых",B17,IF(B35="Считыватель вх",J36,"")) -> пом. 305 | J36: Резерв | R36: *(помещение№)
E42: Стойка | M42: XK | N42: =N21 -> 3.1
E43: Контроллер SV 777 | M43: № | N43: =N42&".1" -> 3.1.1
E44: Плата SV 005 | M44: № | N44: =N23+1 -> 2
E45: Наименование плинтодержателя | M45: ХВ1 | N45: ="-"&N42&".1" -> -3.1.1
E46: Номер плинта | M46: № | N46: =N25+1 -> 3
E47: СКУД | M47: № | N47: 3.3
B50: к SV 005 разъемы R1 и D1
B52: 0 | D52: 1 | E52: 1 | F52: 2 | G52: 2 | H52: 3 | I52: 3 | J52: 4 | K52: 4 | L52: 5 | N52: 6 | O52: 1 | P52: 7 | Q52: 2 | R52: 8 | S52: 3 | T52: 9 | U52: 4
B56: =IF(Q56>1,"Считыватель вх",IF(F56<1,"","Считыватель вх")) -> Считыватель вх | F56: 16 | J56: =IF(Q56>1,"замок",IF(K56<1,"",IF(F56<1,"замок пож.дв.","замок"))) -> замок | K56: 25 | L56: сирена | M56: к ХВ20 | N56: геркон | O56: 22 | P56: кн. Вых | R56: оборудование\ кабель
B57: пом. 350 | R57: *(помещение№)
E61: Стойка | M61: XK | N61: =N42 -> 3.1
E62: Контроллер SV 777 | M62: № | N62: =N42&".1" -> 3.1.1
E63: Плата SV 005 | M63: № | N63: =N44 -> 2
E64: Наименование плинтодержателя | M64: ХВ1 | N64: =N45 -> -3.1.1
E65: Номер плинта | M65: № | N65: =N46+1 -> 4
E66: СКУД | M66: № | N66: 3.3
B69: к SV 005 разъемы R2 и D2
B71: 0 | D71: 1 | E71: 1 | F71: 2 | G71: 2 | H71: 3 | I71: 3 | J71: 4 | K71: 4 | L71: 5 | N71: 6 | O71: 1 | P71: 7 | Q71: 2 | R71: 8 | S71: 3 | T71: 9 | U71: 4
B75: =IF(Q75>1,"Считыватель вх",IF(F75<1,"","Считыватель вых")) -> Считыватель вых | F75: 19 | J75: =IF(Q75>1,"замок",IF(K75<1,"",IF(F75<1,"замок пож.дв.","замок"))) | L75: сирена | M75: к ХВ20 | N75: геркон | P75: кн. Вых | R75: оборудование\ кабель
B76: =IF(B75="Считыватель вых",B57,IF(B75="Считыватель вх",J76,"")) -> пом. 350 | J76: Резерв | R76: *(помещение№)
...

Sheet шпоргалка
D2: SV 777 - ХК3.1
B4: 1 | C4: R1 | D4: ='SV777 - ХК3.1 (SV005)'!B16 -> Считыватель вх | E4: ='SV777 - ХК3.1 (SV005)'!B17 -> пом. 305 | F4: ="ШЛ."&'SV777 - ХК3.1 (SV005)'!F16 -> ШЛ.1 | G4: =IF('SV777 - ХК3.1 (SV005)'!K35<1,"1","1") -> 1
C5: D1 | D5: ='SV777 - ХК3.1 (SV005)'!J16 -> замок | E5: ='SV777 - ХК3.1 (SV005)'!B17 -> пом. 305 | F5: ="СКД."&'SV777 - ХК3.1 (SV005)'!N7 -> СКД.3.1
C6: R2 | D6: ='SV777 - ХК3.1 (SV005)'!B35 -> Считыватель вых | E6: ='SV777 - ХК3.1 (SV005)'!B36 -> пом. 305 | F6: ="ШЛ."&'SV777 - ХК3.1 (SV005)'!F35 -> ШЛ.4 | G6: =IF(D6="Считыватель вых","",IF(D6="Считыватель вх",G4+1,""))
C7: D2 | D7: =IF('SV777 - ХК3.1 (SV005)'!K35<1,"………………………….",'SV777 - ХК3.1 (SV005)'!J35) -> …………………………. | E7: =IF('SV777 - ХК3.1 (SV005)'!K35<1,"…………….",IF('SV777 - ХК3.1 (SV005)'!Q35>1,'SV777 - ХК3.1 (SV005)'!B36,'SV777 - ХК3.1 (SV005)'!J36)) -> ……………. | F7: =IF(D6="Считыватель вых","",IF(D7="замок пож.дв.","СКД."&'SV777 - ХК3.1 (SV005)'!N26,"СКД."&'SV777 - ХК3.1 (SV005)'!N26)) | G7: =IF(D7="замок пож.дв.",G4+1,"")
B9: =B4+1 -> 2 | C9: R3 | D9: ='SV777 - ХК3.1 (SV005)'!B56 -> Считыватель вх | E9: ='SV777 - ХК3.1 (SV005)'!B57 -> пом. 350 | F9: ="ШЛ."&'SV777 - ХК3.1 (SV005)'!F56 -> ШЛ.16 | G9: =IF('SV777 - ХК3.1 (SV005)'!K35<1,G4+1,G4+2) -> 2
C10: D3 | D10: ='SV777 - ХК3.1 (SV005)'!J56 -> замок | E10: ='SV777 - ХК3.1 (SV005)'!B57 -> пом. 350 | F10: ="СКД."&'SV777 - ХК3.1 (SV005)'!N47 -> СКД.3.3
C11: R4 | D11: ='SV777 - ХК3.1 (SV005)'!B75 -> Считыватель вых | E11: ='SV777 - ХК3.1 (SV005)'!B76 -> пом. 350 | F11: ="ШЛ."&'SV777 - ХК3.1 (SV005)'!F75 -> ШЛ.19 | G11: =IF(D11="Считыватель вых","",IF(D11="Считыватель вх",G9+1,""))
C12: D4 | D12: =IF('SV777 - ХК3.1 (SV005)'!K75<1,"………………………….",'SV777 - ХК3.1 (SV005)'!J75) -> …………………………. | E12: =IF('SV777 - ХК3.1 (SV005)'!K75<1,"…………….",IF('SV777 - ХК3.1 (SV005)'!Q75>1,'SV777 - ХК3.1 (SV005)'!B76,'SV777 - ХК3.1 (SV005)'!J76)) -> ……………. | F12: =IF(D11="Считыватель вых","",IF(D12="замок пож.дв.","СКД."&'SV777 - ХК3.1 (SV005)'!N66,"СКД."&'SV777 - ХК3.1 (SV005)'!N66)) | G12: =IF(D12="замок пож.дв.",G9+1,"")
B14: =B9+1 -> 3 | C14: R5 | D14: ='SV777 - ХК3.1 (SV005)'!B96 -> Считыватель вх | E14: ='SV777 - ХК3.1 (SV005)'!B97 -> пом. 314 | F14: ="ШЛ."&'SV777 - ХК3.1 (SV005)'!F96 -> ШЛ.58 | G14: =IF('SV777 - ХК3.1 (SV005)'!K75<1,G9+1,G9+2) -> 3
C15: D5 | D15: ='SV777 - ХК3.1 (SV005)'!J96 -> замок | E15: ='SV777 - ХК3.1 (SV005)'!B97 -> пом. 314 | F15: ="СКД."&'SV777 - ХК3.1 (SV005)'!N87 -> СКД.3.4
C16: R6 | D16: ='SV777 - ХК3.1 (SV005)'!B115 -> Считыватель вых | E16: ='SV777 - ХК3.1 (SV005)'!B116 -> пом. 314 | F16: ="ШЛ."&'SV777 - ХК3.1 (SV005)'!F115 -> ШЛ.61 | G16: =IF(D16="Считыватель вых","",IF(D16="Считыватель вх",G14+1,""))
C17: D6 | D17: =IF('SV777 - ХК3.1 (SV005)'!K115<1,"………………………….",'SV777 - ХК3.1 (SV005)'!J115) -> …………………………. | E17: =IF('SV777 - ХК3.1 (SV005)'!K115<1,"…………….",IF('SV777 - ХК3.1 (SV005)'!Q115>1,'SV777 - ХК3.1 (SV005)'!B116,'SV777 - ХК3.1 (SV005)'!J116)) -> ……………. | F17: =IF(D16="Считыватель вых","",IF(D17="замок пож.дв.","СКД."&'SV777 - ХК3.1 (SV005)'!N106,"СКД."&'SV777 - ХК3.1 (SV005)'!N106)) | G17: =IF(D17="замок пож.дв.",G14+1,"")
B19: =B14+1 -> 4 | C19: R7 | D19: ='SV777 - ХК3.1 (SV005)'!B136 -> Считыватель вх | E19: ='SV777 - ХК3.1 (SV005)'!B137 -> пом. 367 | F19: ="ШЛ."&'SV777 - ХК3.1 (SV005)'!F136 -> ШЛ.142 | G19: =IF('SV777 - ХК3.1 (SV005)'!K115<1,G14+1,G14+2) -> 4
C20: D7 | D20: ='SV777 - ХК3.1 (SV005)'!J136 -> замок | E20: ='SV777 - ХК3.1 (SV005)'!B137 -> пом. 367 | F20: ="СКД."&'SV777 - ХК3.1 (SV005)'!N127 -> СКД.3.5
C21: R8 | D21: ='SV777 - ХК3.1 (SV005)'!B155 -> Считыватель вых | E21: ='SV777 - ХК3.1 (SV005)'!B156 -> пом. 367 | F21: ="ШЛ."&'SV777 - ХК3.1 (SV005)'!F155 -> ШЛ.145 | G21: =IF(D21="Считыватель вых","",IF(D21="Считыватель вх",G19+1,""))
C22: D8 | D22: =IF('SV777 - ХК3.1 (SV005)'!K155<1,"………………………….",'SV777 - ХК3.1 (SV005)'!J155) -> …………………………. | E22: =IF('SV777 - ХК3.1 (SV005)'!K155<1,"…………….",IF('SV777 - ХК3.1 (SV005)'!Q155>1,'SV777 - ХК3.1 (SV005)'!B156,'SV777 - ХК3.1 (SV005)'!J156)) -> ……………. | F22: =IF(D21="Считыватель вых","",IF(D22="замок пож.дв.","СКД."&'SV777 - ХК3.1 (SV005)'!N146,"СКД."&'SV777 - ХК3.1 (SV005)'!N146)) | G22: =IF(D22="замок пож.дв.",G19+1,"")
B24: 5 | C24: R9 | D24: Ситывытель вх | E24: пом. 353 | F24: ШЛ.157 | G24: =IF('SV777 - ХК3.1 (SV005)'!K120<1,G19+1,G19+2) -> 5
C25: D9 | D25: замок | E25: пом. 353 | F25: СКД. 3.6
C26: R10 | D26: Ситывытель вых | E26: пом. 353 | F26: ШЛ.160 | G26: =IF(D26="Считыватель вых","",IF(D26="Считыватель вх",G24+1,""))
C27: D10 | D27: =IF('SV777 - ХК3.1 (SV005)'!K160<1,"………………………….",'SV777 - ХК3.1 (SV005)'!J160) -> …………………………. | E27: =IF('SV777 - ХК3.1 (SV005)'!K160<1,"…………….",IF('SV777 - ХК3.1 (SV005)'!Q160>1,'SV777 - ХК3.1 (SV005)'!B161,'SV777 - ХК3.1 (SV005)'!J161)) -> ……………. | F27: =IF('SV777 - ХК3.1 (SV005)'!L160<1,"…………….",IF('SV777 - ХК3.1 (SV005)'!R160>1,'SV777 - ХК3.1 (SV005)'!C161,'SV777 - ХК3.1 (SV005)'!K161)) -> ……………. | G27: =IF(D27="замок пож.дв.",G24+1,"")
B29: 6 | C29: R11 | D29: Считывытель вх | E29: пом. 368 | F29: ШЛ. 73 | G29: =IF('SV777 - ХК3.1 (SV005)'!K125<1,G24+1,G24+2) -> 6
C30: D11 | D30: Замок | E30: пом. 368 | F30: СКД. 3.2
C31: R12 | D31: кн. Выхода | E31: пом. 368 | F31: ШЛ. 76 | G31: =IF(D31="Считыватель вых","",IF(D31="Считыватель вх",G29+1,""))
C32: D12 | D32: =IF('SV777 - ХК3.1 (SV005)'!K165<1,"………………………….",'SV777 - ХК3.1 (SV005)'!J165) -> …………………………. | E32: =IF('SV777 - ХК3.1 (SV005)'!K165<1,"…………….",IF('SV777 - ХК3.1 (SV005)'!Q165>1,'SV777 - ХК3.1 (SV005)'!B166,'SV777 - ХК3.1 (SV005)'!J166)) -> ……………. | F32: =IF('SV777 - ХК3.1 (SV005)'!L165<1,"…………….",IF('SV777 - ХК3.1 (SV005)'!R165>1,'SV777 - ХК3.1 (SV005)'!C166,'SV777 - ХК3.1 (SV005)'!K166)) -> ……………. | G32: =IF(D32="замок пож.дв.",G29+1,"")
