Workbook

Sheet SV777-1 (SV004)
A1: *******************************************************************************************
E2: Стойка | M2: XK | N2: 2.1
E3: Контроллер SV 777 | M3: № | N3: ХК 2.1.1
E4: Плата SV 004 | M4: № | N4: 1
E5: Наименование плинтодержателя | M5: № | N5: ХВ-2.1.1
E6: Номер плинта | M6: № | N6: 13
D9: 1 | H9: 2 | L9: 3 | P9: 4
B10: к БП | D10: к SV 004* | F10: к БП | H10: к SV 004* | J10: к БП | L10: к SV 004* | N10: к БП | P10: к SV 004*
B12: 0 | D12: 1 | F12: 2 | H12: 3 | J12: 4 | L12: 5 | N12: 6 | P12: 7 | R12: 8 | T12: 9
B13: A | C13: B | D13: C | E13: D | F13: A | G13: B | H13: C | I13: D | J13: A | K13: B | L13: C | M13: D | N13: A | O13: B | P13: C | Q13: D | R13: A | S13: B | T13: C | U13: D
B15: КАВ (1) | D15: 10 | F15: КАВ (1) | H15: 43 | J15: КАВ (1) | L15: 55 | N15: КАВ (1) | P15: 130
B17: пом. | D17: 14 | F17: пом. | H17: 17 | J17: пом. | L17: 17 | N17: пом. | P17: 20
E19: A - | F19: питание "+" | I19: красный | O19: C - | P19: сигнальный | S19: синий
E20: B - | F20: питание "-" | I20: черный | O20: D - | P20: сигнальный | S20: коричневый
A21: *******************************************************************************************
E22: Стойка | M22: XK | N22: 2.1
E23: Контроллер SV 777 | M23: № | N23: ХК 2.1.1
E24: Плата SV 004 | M24: № | N24: 1
E25: Наименование плинтодержателя | M25: № | N25: ХВ-2.1.1
E26: Номер плинта | M26: № | N26: 14
D29: 1 | H29: 2 | L29: 3 | P29: 4
B30: к БП | D30: к SV 004* | F30: к БП | H30: к SV 004* | J30: к БП | L30: к SV 004* | N30: к БП | P30: к SV 004*
B32: 0 | D32: 1 | F32: 2 | H32: 3 | J32: 4 | L32: 5 | N32: 6 | P32: 7 | R32: 8 | T32: 9
B33: A | C33: B | D33: C | E33: D | F33: A | G33: B | H33: C | I33: D | J33: A | K33: B | L33: C | M33: D | N33: A | O33: B | P33: C | Q33: D | R33: A | S33: B | T33: C | U33: D
B35: КАВ (1) | D35: 109 | F35: КАВ (1) | H35: 163 | J35: ИК (1) | L35: 16 | N35: ИК (1) | P35: 22
B37: пом. | D37: 19 | F37: пом. | H37: 23 | J37: пом. | L37: 14 | N37: пом. | P37: 15
E39: A - | F39: питание "+" | I39: красный | O39: C - | P39: сигнальный | S39: синий
E40: B - | F40: питание "-" | I40: черный | O40: D - | P40: сигнальный | S40: коричневый
A41: *******************************************************************************************
E42: Стойка | M42: XK | N42: 2.1
E43: Контроллер SV 777 | M43: № | N43: ХК 2.1.1
E44: Плата SV 004 | M44: № | N44: 2
E45: Наименование плинтодержателя | M45: № | N45: ХВ-2.1.1
E46: Номер плинта | M46: № | N46: 15
D49: 1 | H49: 2 | L49: 3 | P49: 4
B50: к БП | D50: к SV 004* | F50: к БП | H50: к SV 004* | J50: к БП | L50: к SV 004* | N50: к БП | P50: к SV 004*
B52: 0 | D52: 1 | F52: 2 | H52: 3 | J52: 4 | L52: 5 | N52: 6 | P52: 7 | R52: 8 | T52: 9
B53: A | C53: B | D53: C | E53: D | F53: A | G53: B | H53: C | I53: D | J53: A | K53: B | L53: C | M53: D | N53: A | O53: B | P53: C | Q53: D | R53: A | S53: B | T53: C | U53: D
B55: ИК (1) | D55: 28 | F55: ИК (6) | H55: 64 | J55: ИК (1) | L55: 94 | N55: СМК (1), ИК (1) | P55: 170
B57: пом. | D57: 16 | F57: пом. | H57: 17 | J57: пом. | L57: 18 | N57: пом. | P57: ДГУ
...

Sheet SV777-2 (SV004)
E2: Стойка | M2: XK | N2: 1.1 | AB2: Стойка | AJ2: XK | AK2: 1.1
E3: Контроллер SV 777 | M3: № | N3: =N2&".2" -> 1.1.2 | AB3: Контроллер SV 777 | AJ3: № | AK3: =AK2&".2" -> 1.1.2
E4: Плата SV 004 | M4: № | N4: 1 | AB4: RS 485 | AJ4: № | AK4: 1
E5: Наименование плинтодержателя | M5: XB1 | N5: ="-"&N2&".3" -> -1.1.3 | AB5: Наименование плинтодержателя | AJ5: XB1 | AK5: ="-"&AK2&".4" -> -1.1.4
E6: Номер плинта | M6: № | N6: 1 | AB6: Номер плинта | AJ6: № | AK6: 18
D9: 1 | H9: 2 | L9: 3 | P9: 4 | X9: 1 | AB9: 2 | AF9: 3 | AJ9: 4
B10: к БП | D10: к SV 004* | F10: к БП | H10: к SV 004* | J10: к БП | L10: к SV 004* | N10: к БП | P10: к SV 004* | X10: SV20P | Z10: GND | AB10: SVDPO | AD10: GND | AF10: 485 | AH10: GND | AJ10: 485 | AL10: GND
X11: COM-1 | AB11: COM-2 | AF11: COM-3
B12: 0 | D12: 1 | F12: 2 | H12: 3 | J12: 4 | L12: 5 | N12: 6 | P12: 7 | R12: 8 | T12: 9 | X12: 0 | Z12: 1 | AB12: 2 | AD12: 3 | AF12: 4 | AH12: 5 | AJ12: 6 | AL12: 7 | AN12: 8 | AP12: 9
B13: A | C13: B | D13: C | E13: D | F13: A | G13: B | H13: C | I13: D | J13: A | K13: B | L13: C | M13: D | N13: A | O13: B | P13: C | Q13: D | R13: A | S13: B | T13: C | U13: D | X13: 1 | Y13: 2 | Z13: 5 | AB13: 1 | AC13: 2 | AD13: 5 | AF13: 1 | AG13: 2 | AH13: 5 | AJ13: 1 | AK13: 2 | AL13: 5
X15: RS-485 1.1 | AB15: RS-485 1.1
X16: земля.5 | AB16: земля.5
F17: =IF(H16<1,"","пом.") | J17: =IF(L16<1,"","пом.") | N17: =IF(P16<1,"","пом.")
E19: A - | F19: питание "+" | I19: красный | O19: C - | P19: сигнальный | S19: синий | X19: RS-485
E20: B - | F20: питание "-" | I20: черный | O20: D - | P20: сигнальный | S20: желтый | X20: COM-1 | AB20: COM-2 | AF20: COM-3 | AJ20: COM-4
X21: Device | Z21: adress | AB21: Device | AD21: adress | AF21: Device | AH21: adress | AJ21: Device | AL21: adress
E22: Стойка | M22: XK | N22: =N2 -> 1.1 | X22: SV20P | Z22: 1 | AB22: SVDPO | AD22: 1
E23: Контроллер SV 777 | M23: № | N23: =N3 -> 1.1.2 | AB23: SVDPO | AD23: 2
E24: Плата SV 004 | M24: № | N24: =N4 -> 1
E25: Наименование плинтодержателя | M25: XB1 | N25: =IF(N5="-"&N2&".3",IF(N6=15,"-"&N2&".4","-"&N2&".3"),N5) -> -1.1.3
E26: Номер плинта | M26: № | N26: =IF(N25="-"&N2&".3",N6+1,1) -> 2
D29: 1 | H29: 2 | L29: 3 | P29: 4
B30: к БП | D30: к SV 004* | F30: к БП | H30: к SV 004* | J30: к БП | L30: к SV 004* | N30: к БП | P30: к SV 004*
B32: 0 | D32: 1 | F32: 2 | H32: 3 | J32: 4 | L32: 5 | N32: 6 | P32: 7 | R32: 8 | T32: 9
B33: A | C33: B | D33: C | E33: D | F33: A | G33: B | H33: C | I33: D | J33: A | K33: B | L33: C | M33: D | N33: A | O33: B | P33: C | Q33: D | R33: A | S33: B | T33: C | U33: D
B37: =IF(D36<1,"","пом.") | F37: =IF(H36<1,"","пом.") | J37: =IF(L36<1,"","пом.") | N37: =IF(P36<1,"","пом.")
E39: A - | F39: питание "+" | I39: красный | O39: C - | P39: сигнальный | S39: синий
E40: B - | F40: питание "-" | I40: черный | O40: D - | P40: сигнальный | S40: желтый
E44: Стойка | M44: XK | N44: =N22 -> 1.1
E45: Контроллер SV 777 | M45: № | N45: =N44&".2" -> 1.1.2
E46: Плата SV 004 | M46: № | N46: =N24+1 -> 2
E47: Наименование плинтодержателя | M47: XB1 | N47: =IF(N25="-"&N2&".3",IF(N26=15,"-"&N2&".4","-"&N2&".3"),N25) -> -1.1.3
E48: Номер плинта | M48: № | N48: =IF(N47="-"&N2&".3",N26+1,IF(N25="-"&N2&".3",1,N26+1)) -> 3
D51: 1 | H51: 2 | L51: 3 | P51: 4
B52: к БП | D52: к SV 004* | F52: к БП | H52: к SV 004* | J52: к БП | L52: к SV 004* | N52: к БП | P52: к SV 004*
B54: 0 | D54: 1 | F54: 2 | H54: 3 | J54: 4 | L54: 5 | N54: 6 | P54: 7 | R54: 8 | T54: 9
B55: A | C55: B | D55: C | E55: D | F55: A | G55: B | H55: C | I55: D | J55: A | K55: B | L55: C | M55: D | N55: A | O55: B | P55: C | Q55: D | R55: A | S55: B | T55: C | U55: D
B59: =IF(D58<1,"","пом.") | F59: =IF(H58<1,"","пом.") | J59: =IF(L58<1,"","пом.") | N59: =IF(P58<1,"","пом.")
E61: A - | F61: питание "+" | I61: красный | O61: C - | P61: сигнальный | S61: синий
E62: B - | F62: питание "-" | I62: черный | O62: D - | P62: сигнальный | S62: желтый
...

Sheet SV777-3 (SV004)
E2: Стойка | M2: XK | N2: 1.1 | AB2: Стойка | AJ2: XK | AK2: 1.1
E3: Контроллер SV 777 | M3: № | N3: =N2&".3" -> 1.1.3 | AB3: Контроллер SV 777 | AJ3: № | AK3: =AK2&".3" -> 1.1.3
E4: Плата SV 004 | M4: № | N4: 1 | AB4: SV 485 | AJ4: № | AK4: 1
E5: Наименование плинтодержателя | M5: XB1 | N5: ="-"&N2&".5" -> -1.1.5 | AB5: Наименование плинтодержателя | AJ5: XB1 | AK5: ="-"&AK2&".6" -> -1.1.6
E6: Номер плинта | M6: № | N6: 1 | AB6: Номер плинта | AJ6: № | AK6: 18
D9: 1 | H9: 2 | L9: 3 | P9: 4 | X9: 1 | AB9: 2 | AF9: 3 | AJ9: 4
B10: к БП | D10: к SV 004* | F10: к БП | H10: к SV 004* | J10: к БП | L10: к SV 004* | N10: к БП | P10: к SV 004* | X10: SV20P | Z10: GND | AB10: SVDPO | AD10: GND | AF10: 485 | AH10: GND | AJ10: 485 | AL10: GND
X11: COM-1 | AB11: COM-2 | AF11: COM-3
B12: 0 | D12: 1 | F12: 2 | H12: 3 | J12: 4 | L12: 5 | N12: 6 | P12: 7 | R12: 8 | T12: 9 | X12: 0 | Z12: 1 | AB12: 2 | AD12: 3 | AF12: 4 | AH12: 5 | AJ12: 6 | AL12: 7 | AN12: 8 | AP12: 9
B13: A | C13: B | D13: C | E13: D | F13: A | G13: B | H13: C | I13: D | J13: A | K13: B | L13: C | M13: D | N13: A | O13: B | P13: C | Q13: D | R13: A | S13: B | T13: C | U13: D | X13: 1 | Y13: 2 | Z13: 5 | AB13: 1 | AC13: 2 | AD13: 5 | AF13: 1 | AG13: 2 | AH13: 5 | AJ13: 1 | AK13: 2 | AL13: 5
X15: RS-485 1.1 | AB15: RS-485 1.1
X16: земля.5 | AB16: земля.5
B17: =IF(D16<1,"","пом.") | F17: =IF(H16<1,"","пом.") | J17: =IF(L16<1,"","пом.") | N17: =IF(P16<1,"","пом.")
E19: A - | F19: питание "+" | I19: красный | O19: C - | P19: сигнальный | S19: синий | X19: RS-485
E20: B - | F20: питание "-" | I20: черный | O20: D - | P20: сигнальный | S20: коричневый | X20: COM-1 | AB20: COM-2 | AF20: COM-3 | AJ20: COM-4
X21: Device | Z21: adress | AB21: Device | AD21: adress | AF21: Device | AH21: adress | AJ21: Device | AL21: adress
E22: Стойка | M22: XK | N22: =N2 -> 1.1 | X22: SV20P | Z22: 1 | AB22: SVDPO | AD22: 1
E23: Контроллер SV 777 | M23: № | N23: =N3 -> 1.1.3 | AB23: SVDPO | AD23: 2
E24: Плата SV 004 | M24: № | N24: =N4 -> 1
E25: Наименование плинтодержателя | M25: XB1 | N25: =IF(N5="-"&N2&".5",IF(N6=15,"-"&N2&".6","-"&N2&".5"),N5) -> -1.1.5
E26: Номер плинта | M26: № | N26: =IF(N25="-"&N2&".5",N6+1,1) -> 2
D29: 1 | H29: 2 | L29: 3 | P29: 4
B30: к БП | D30: к SV 004* | F30: к БП | H30: к SV 004* | J30: к БП | L30: к SV 004* | N30: к БП | P30: к SV 004*
B32: 0 | D32: 1 | F32: 2 | H32: 3 | J32: 4 | L32: 5 | N32: 6 | P32: 7 | R32: 8 | T32: 9
B33: A | C33: B | D33: C | E33: D | F33: A | G33: B | H33: C | I33: D | J33: A | K33: B | L33: C | M33: D | N33: A | O33: B | P33: C | Q33: D | R33: A | S33: B | T33: C | U33: D
B37: =IF(D36<1,"","пом.") | F37: =IF(H36<1,"","пом.") | J37: =IF(L36<1,"","пом.") | N37: =IF(P36<1,"","пом.")
E39: A - | F39: питание "+" | I39: красный | O39: C - | P39: сигнальный | S39: синий
E40: B - | F40: питание "-" | I40: черный | O40: D - | P40: сигнальный | S40: коричневый
E44: Стойка | M44: XK | N44: =N22 -> 1.1
E45: Контроллер SV 777 | M45: № | N45: =N44&".3" -> 1.1.3
E46: Плата SV 004 | M46: № | N46: =N24+1 -> 2
E47: Наименование плинтодержателя | M47: XB1 | N47: =IF(N25="-"&N2&".5",IF(N26=15,"-"&N2&".6","-"&N2&".5"),N25) -> -1.1.5
E48: Номер плинта | M48: № | N48: =IF(N47="-"&N2&".5",N26+1,IF(N25="-"&N2&".5",1,N26+1)) -> 3
D51: 1 | H51: 2 | L51: 3 | P51: 4
B52: к БП | D52: к SV 004* | F52: к БП | H52: к SV 004* | J52: к БП | L52: к SV 004* | N52: к БП | P52: к SV 004*
B54: 0 | D54: 1 | F54: 2 | H54: 3 | J54: 4 | L54: 5 | N54: 6 | P54: 7 | R54: 8 | T54: 9
B55: A | C55: B | D55: C | E55: D | F55: A | G55: B | H55: C | I55: D | J55: A | K55: B | L55: C | M55: D | N55: A | O55: B | P55: C | Q55: D | R55: A | S55: B | T55: C | U55: D
B59: =IF(D58<1,"","пом.") | F59: =IF(H58<1,"","пом.") | J59: =IF(L58<1,"","пом.") | N59: =IF(P58<1,"","пом.")
E61: A - | F61: питание "+" | I61: красный | O61: C - | P61: сигнальный | S61: синий
E62: B - | F62: питание "-" | I62: черный | O62: D - | P62: сигнальный | S62: коричневый
...

Sheet шпоргалка-1
C2: SV777 - 1
B3: SV004 -1
A4: 1 | B4: =IF('SV777-1 (SV004)'!B16<1,"резерв",'SV777-1 (SV004)'!B16) -> резерв | C4: ='SV777-1 (SV004)'!B17 -> 0 | D4: =IF(B4="резерв","",'SV777-1 (SV004)'!D17) | E4: =IF('SV777-1 (SV004)'!D16<1,"","ШЛ."&'SV777-1 (SV004)'!D16)
A5: 2 | B5: =IF('SV777-1 (SV004)'!F16<1,"резерв",'SV777-1 (SV004)'!F16) -> резерв | C5: ='SV777-1 (SV004)'!F17 -> 0 | D5: =IF(B5="резерв","",'SV777-1 (SV004)'!H17) | E5: =IF('SV777-1 (SV004)'!H16<1,"","ШЛ."&'SV777-1 (SV004)'!H16)
A6: 3 | B6: =IF('SV777-1 (SV004)'!J16<1,"резерв",'SV777-1 (SV004)'!J16) -> резерв | C6: ='SV777-1 (SV004)'!J17 -> 0 | D6: =IF(B6="резерв","",'SV777-1 (SV004)'!L17) | E6: =IF('SV777-1 (SV004)'!L16<1,"","ШЛ."&'SV777-1 (SV004)'!L16)
A7: 4 | B7: =IF('SV777-1 (SV004)'!N16<1,"резерв",'SV777-1 (SV004)'!N16) -> резерв | C7: ='SV777-1 (SV004)'!N17 -> 0 | D7: =IF(B7="резерв","",'SV777-1 (SV004)'!P17) | E7: =IF('SV777-1 (SV004)'!P16<1,"","ШЛ."&'SV777-1 (SV004)'!P16)
A8: 5 | B8: =IF('SV777-1 (SV004)'!#REF!<1,"резерв",'SV777-1 (SV004)'!#REF!) -> #REF! | C8: ='SV777-1 (SV004)'!#REF! -> #REF! | D8: =IF(B8="резерв","",'SV777-1 (SV004)'!#REF!) -> #REF! | E8: =IF('SV777-1 (SV004)'!#REF!<1,"","ШЛ."&'SV777-1 (SV004)'!#REF!) -> #REF!
A9: 6 | B9: =IF('SV777-1 (SV004)'!#REF!<1,"резерв",'SV777-1 (SV004)'!#REF!) -> #REF! | C9: ='SV777-1 (SV004)'!#REF! -> #REF! | D9: =IF(B9="резерв","",'SV777-1 (SV004)'!#REF!) -> #REF! | E9: =IF('SV777-1 (SV004)'!#REF!<1,"","ШЛ."&'SV777-1 (SV004)'!#REF!) -> #REF!
A10: 7 | B10: =IF('SV777-1 (SV004)'!#REF!<1,"резерв",'SV777-1 (SV004)'!#REF!) -> #REF! | C10: ='SV777-1 (SV004)'!#REF! -> #REF! | D10: =IF(B10="резерв","",'SV777-1 (SV004)'!#REF!) -> #REF! | E10: =IF('SV777-1 (SV004)'!#REF!<1,"","ШЛ."&'SV777-1 (SV004)'!#REF!) -> #REF!
A11: 8 | B11: =IF('SV777-1 (SV004)'!#REF!<1,"резерв",'SV777-1 (SV004)'!#REF!) -> #REF! | C11: ='SV777-1 (SV004)'!#REF! -> #REF! | D11: =IF(B11="резерв","",'SV777-1 (SV004)'!#REF!) -> #REF! | E11: =IF('SV777-1 (SV004)'!#REF!<1,"","ШЛ."&'SV777-1 (SV004)'!#REF!) -> #REF!
B12: SV004 - 2
A13: 1 | B13: =IF('SV777-1 (SV004)'!#REF!<1,"резерв",'SV777-1 (SV004)'!#REF!) -> #REF! | C13: ='SV777-1 (SV004)'!#REF! -> #REF! | D13: =IF(B13="резерв","",'SV777-1 (SV004)'!#REF!) -> #REF! | E13: =IF('SV777-1 (SV004)'!#REF!<1,"","ШЛ."&'SV777-1 (SV004)'!#REF!) -> #REF!
A14: 2 | B14: =IF('SV777-1 (SV004)'!#REF!<1,"резерв",'SV777-1 (SV004)'!#REF!) -> #REF! | C14: ='SV777-1 (SV004)'!#REF! -> #REF! | D14: =IF(B14="резерв","",'SV777-1 (SV004)'!#REF!) -> #REF! | E14: =IF('SV777-1 (SV004)'!#REF!<1,"","ШЛ."&'SV777-1 (SV004)'!#REF!) -> #REF!
A15: 3 | B15: =IF('SV777-1 (SV004)'!#REF!<1,"резерв",'SV777-1 (SV004)'!#REF!) -> #REF! | C15: ='SV777-1 (SV004)'!#REF! -> #REF! | D15: =IF(B15="резерв","",'SV777-1 (SV004)'!#REF!) -> #REF! | E15: =IF('SV777-1 (SV004)'!#REF!<1,"","ШЛ."&'SV777-1 (SV004)'!#REF!) -> #REF!
A16: 4 | B16: =IF('SV777-1 (SV004)'!#REF!<1,"резерв",'SV777-1 (SV004)'!#REF!) -> #REF! | C16: ='SV777-1 (SV004)'!#REF! -> #REF! | D16: =IF(B16="резерв","",'SV777-1 (SV004)'!#REF!) -> #REF! | E16: =IF('SV777-1 (SV004)'!#REF!<1,"","ШЛ."&'SV777-1 (SV004)'!#REF!) -> #REF!
A17: 5 | B17: =IF('SV777-1 (SV004)'!#REF!<1,"резерв",'SV777-1 (SV004)'!#REF!) -> #REF! | C17: ='SV777-1 (SV004)'!#REF! -> #REF! | D17: =IF(B17="резерв","",'SV777-1 (SV004)'!#REF!) -> #REF! | E17: =IF('SV777-1 (SV004)'!#REF!<1,"","ШЛ."&'SV777-1 (SV004)'!#REF!) -> #REF!
A18: 6 | B18: =IF('SV777-1 (SV004)'!#REF!<1,"резерв",'SV777-1 (SV004)'!#REF!) -> #REF! | C18: ='SV777-1 (SV004)'!#REF! -> #REF! | D18: =IF(B18="резерв","",'SV777-1 (SV004)'!#REF!) -> #REF! | E18: =IF('SV777-1 (SV004)'!#REF!<1,"","ШЛ."&'SV777-1 (SV004)'!#REF!) -> #REF!
A19: 7 | B19: =IF('SV777-1 (SV004)'!#REF!<1,"резерв",'SV777-1 (SV004)'!#REF!) -> #REF! | C19: ='SV777-1 (SV004)'!#REF! -> #REF! | D19: =IF(B19="резерв","",'SV777-1 (SV004)'!#REF!) -> #REF! | E19: =IF('SV777-1 (SV004)'!#REF!<1,"","ШЛ."&'SV777-1 (SV004)'!#REF!) -> #REF!
A20: 8 | B20: =IF('SV777-1 (SV004)'!#REF!<1,"резерв",'SV777-1 (SV004)'!#REF!) -> #REF! | C20: ='SV777-1 (SV004)'!#REF! -> #REF! | D20: =IF(B20="резерв","",'SV777-1 (SV004)'!#REF!) -> #REF! | E20: =IF('SV777-1 (SV004)'!#REF!<1,"","ШЛ."&'SV777-1 (SV004)'!#REF!) -> #REF!
B21: SV004 - 3
A22: 1 | B22: =IF('SV777-1 (SV004)'!#REF!<1,"резерв",'SV777-1 (SV004)'!#REF!) -> #REF! | C22: ='SV777-1 (SV004)'!#REF! -> #REF! | D22: =IF(B22="резерв","",'SV777-1 (SV004)'!#REF!) -> #REF! | E22: =IF('SV777-1 (SV004)'!#REF!<1,"","ШЛ."&'SV777-1 (SV004)'!#REF!) -> #REF!
A23: 2 | B23: =IF('SV777-1 (SV004)'!#REF!<1,"резерв",'SV777-1 (SV004)'!#REF!) -> #REF! | C23: ='SV777-1 (SV004)'!#REF! -> #REF! | D23: =IF(B23="резерв","",'SV777-1 (SV004)'!#REF!) -> #REF! | E23: =IF('SV777-1 (SV004)'!#REF!<1,"","ШЛ."&'SV777-1 (SV004)'!#REF!) -> #REF!
A24: 3 | B24: =IF('SV777-1 (SV004)'!#REF!<1,"резерв",'SV777-1 (SV004)'!#REF!) -> #REF! | C24: ='SV777-1 (SV004)'!#REF! -> #REF! | D24: =IF(B24="резерв","",'SV777-1 (SV004)'!#REF!) -> #REF! | E24: =IF('SV777-1 (SV004)'!#REF!<1,"","ШЛ."&'SV777-1 (SV004)'!#REF!) -> #REF!
A25: 4 | B25: =IF('SV777-1 (SV004)'!#REF!<1,"резерв",'SV777-1 (SV004)'!#REF!) -> #REF! | C25: ='SV777-1 (SV004)'!#REF! -> #REF! | D25: =IF(B25="резерв","",'SV777-1 (SV004)'!#REF!) -> #REF! | E25: =IF('SV777-1 (SV004)'!#REF!<1,"","ШЛ."&'SV777-1 (SV004)'!#REF!) -> #REF!
A26: 5 | B26: =IF('SV777-1 (SV004)'!#REF!<1,"резерв",'SV777-1 (SV004)'!#REF!) -> #REF! | C26: ='SV777-1 (SV004)'!#REF! -> #REF! | D26: =IF(B26="резерв","",'SV777-1 (SV004)'!#REF!) -> #REF! | E26: =IF('SV777-1 (SV004)'!#REF!<1,"","ШЛ."&'SV777-1 (SV004)'!#REF!) -> #REF!
A27: 6 | B27: =IF('SV777-1 (SV004)'!#REF!<1,"резерв",'SV777-1 (SV004)'!#REF!) -> #REF! | C27: ='SV777-1 (SV004)'!#REF! -> #REF! | D27: =IF(B27="резерв","",'SV777-1 (SV004)'!#REF!) -> #REF! | E27: =IF('SV777-1 (SV004)'!#REF!<1,"","ШЛ."&'SV777-1 (SV004)'!#REF!) -> #REF!
A28: 7 | B28: =IF('SV777-1 (SV004)'!#REF!<1,"резерв",'SV777-1 (SV004)'!#REF!) -> #REF! | C28: ='SV777-1 (SV004)'!#REF! -> #REF! | D28: =IF(B28="резерв","",'SV777-1 (SV004)'!#REF!) -> #REF! | E28: =IF('SV777-1 (SV004)'!#REF!<1,"","ШЛ."&'SV777-1 (SV004)'!#REF!) -> #REF!
A29: 8 | B29: =IF('SV777-1 (SV004)'!#REF!<1,"резерв",'SV777-1 (SV004)'!#REF!) -> #REF! | C29: ='SV777-1 (SV004)'!#REF! -> #REF! | D29: =IF(B29="резерв","",'SV777-1 (SV004)'!#REF!) -> #REF! | E29: =IF('SV777-1 (SV004)'!#REF!<1,"","ШЛ."&'SV777-1 (SV004)'!#REF!) -> #REF!
B30: SV004 - 4
A31: 1 | B31: =IF('SV777-1 (SV004)'!#REF!<1,"резерв",'SV777-1 (SV004)'!#REF!) -> #REF! | C31: ='SV777-1 (SV004)'!#REF! -> #REF! | D31: =IF(B31="резерв","",'SV777-1 (SV004)'!#REF!) -> #REF! | E31: =IF('SV777-1 (SV004)'!#REF!<1,"","ШЛ."&'SV777-1 (SV004)'!#REF!) -> #REF!
A32: 2 | B32: =IF('SV777-1 (SV004)'!#REF!<1,"резерв",'SV777-1 (SV004)'!#REF!) -> #REF! | C32: ='SV777-1 (SV004)'!#REF! -> #REF! | D32: =IF(B32="резерв","",'SV777-1 (SV004)'!#REF!) -> #REF! | E32: =IF('SV777-1 (SV004)'!#REF!<1,"","ШЛ."&'SV777-1 (SV004)'!#REF!) -> #REF!
A33: 3 | B33: =IF('SV777-1 (SV004)'!#REF!<1,"резерв",'SV777-1 (SV004)'!#REF!) -> #REF! | C33: ='SV777-1 (SV004)'!#REF! -> #REF! | D33: =IF(B33="резерв","",'SV777-1 (SV004)'!#REF!) -> #REF! | E33: =IF('SV777-1 (SV004)'!#REF!<1,"","ШЛ."&'SV777-1 (SV004)'!#REF!) -> #REF!
A34: 4 | B34: =IF('SV777-1 (SV004)'!#REF!<1,"резерв",'SV777-1 (SV004)'!#REF!) -> #REF! | C34: ='SV777-1 (SV004)'!#REF! -> #REF! | D34: =IF(B34="резерв","",'SV777-1 (SV004)'!#REF!) -> #REF! | E34: =IF('SV777-1 (SV004)'!#REF!<1,"","ШЛ."&'SV777-1 (SV004)'!#REF!) -> #REF!
A35: 5 | B35: =IF('SV777-1 (SV004)'!#REF!<1,"резерв",'SV777-1 (SV004)'!#REF!) -> #REF! | C35: ='SV777-1 (SV004)'!#REF! -> #REF! | D35: =IF(B35="резерв","",'SV777-1 (SV004)'!#REF!) -> #REF! | E35: =IF('SV777-1 (SV004)'!#REF!<1,"","ШЛ."&'SV777-1 (SV004)'!#REF!) -> #REF!
A36: 6 | B36: =IF('SV777-1 (SV004)'!#REF!<1,"резерв",'SV777-1 (SV004)'!#REF!) -> #REF! | C36: ='SV777-1 (SV004)'!#REF! -> #REF! | D36: =IF(B36="резерв","",'SV777-1 (SV004)'!#REF!) -> #REF! | E36: =IF('SV777-1 (SV004)'!#REF!<1,"","ШЛ."&'SV777-1 (SV004)'!#REF!) -> #REF!
A37: 7 | B37: =IF('SV777-1 (SV004)'!#REF!<1,"резерв",'SV777-1 (SV004)'!#REF!) -> #REF! | C37: ='SV777-1 (SV004)'!#REF! -> #REF! | D37: =IF(B37="резерв","",'SV777-1 (SV004)'!#REF!) -> #REF! | E37: =IF('SV777-1 (SV004)'!#REF!<1,"","ШЛ."&'SV777-1 (SV004)'!#REF!) -> #REF!
A38: 8 | B38: =IF('SV777-1 (SV004)'!#REF!<1,"резерв",'SV777-1 (SV004)'!#REF!) -> #REF! | C38: ='SV777-1 (SV004)'!#REF! -> #REF! | D38: =IF(B38="резерв","",'SV777-1 (SV004)'!#REF!) -> #REF! | E38: =IF('SV777-1 (SV004)'!#REF!<1,"","ШЛ."&'SV777-1 (SV004)'!#REF!) -> #REF!
B39: SV004 - 5
A40: 1 | B40: =IF('SV777-1 (SV004)'!#REF!<1,"резерв",'SV777-1 (SV004)'!#REF!) -> #REF! | C40: ='SV777-1 (SV004)'!#REF! -> #REF! | D40: =IF(B40="резерв","",'SV777-1 (SV004)'!#REF!) -> #REF! | E40: =IF('SV777-1 (SV004)'!#REF!<1,"","ШЛ."&'SV777-1 (SV004)'!#REF!) -> #REF!
A41: 2 | B41: =IF('SV777-1 (SV004)'!#REF!<1,"резерв",'SV777-1 (SV004)'!#REF!) -> #REF! | C41: ='SV777-1 (SV004)'!#REF! -> #REF! | D41: =IF(B41="резерв","",'SV777-1 (SV004)'!#REF!) -> #REF! | E41: =IF('SV777-1 (SV004)'!#REF!<1,"","ШЛ."&'SV777-1 (SV004)'!#REF!) -> #REF!
...

Sheet шпоргалка-2
C2: SV777 - 2
B3: SV004 - 1
A4: 1 | B4: =IF('SV777-2 (SV004)'!B16<1,"резерв",'SV777-2 (SV004)'!B16) -> резерв | C4: ='SV777-2 (SV004)'!B17 -> 0 | D4: =IF(B4="резерв","",'SV777-2 (SV004)'!D17) | E4: =IF('SV777-2 (SV004)'!D16<1,"","ШЛ."&'SV777-2 (SV004)'!D16)
A5: 2 | B5: =IF('SV777-2 (SV004)'!F16<1,"резерв",'SV777-2 (SV004)'!F16) -> резерв | C5: ='SV777-2 (SV004)'!F17 | D5: =IF(B5="резерв","",'SV777-2 (SV004)'!H17) | E5: =IF('SV777-2 (SV004)'!H16<1,"","ШЛ."&'SV777-2 (SV004)'!H16)
A6: 3 | B6: =IF('SV777-2 (SV004)'!J16<1,"резерв",'SV777-2 (SV004)'!J16) -> резерв | C6: ='SV777-2 (SV004)'!J17 | D6: =IF(B6="резерв","",'SV777-2 (SV004)'!L17) | E6: =IF('SV777-2 (SV004)'!L16<1,"","ШЛ."&'SV777-2 (SV004)'!L16)
A7: 4 | B7: =IF('SV777-2 (SV004)'!N16<1,"резерв",'SV777-2 (SV004)'!N16) -> резерв | C7: ='SV777-2 (SV004)'!N17 | D7: =IF(B7="резерв","",'SV777-2 (SV004)'!P17) | E7: =IF('SV777-2 (SV004)'!P16<1,"","ШЛ."&'SV777-2 (SV004)'!P16)
A8: 5 | B8: =IF('SV777-2 (SV004)'!B36<1,"резерв",'SV777-2 (SV004)'!B36) -> резерв | C8: ='SV777-2 (SV004)'!B37 | D8: =IF(B8="резерв","",'SV777-2 (SV004)'!D37) | E8: =IF('SV777-2 (SV004)'!D36<1,"","ШЛ."&'SV777-2 (SV004)'!D36)
A9: 6 | B9: =IF('SV777-2 (SV004)'!F36<1,"резерв",'SV777-2 (SV004)'!F36) -> резерв | C9: ='SV777-2 (SV004)'!F37 | D9: =IF(B9="резерв","",'SV777-2 (SV004)'!H37) | E9: =IF('SV777-2 (SV004)'!H36<1,"","ШЛ."&'SV777-2 (SV004)'!H36)
A10: 7 | B10: =IF('SV777-2 (SV004)'!J36<1,"резерв",'SV777-2 (SV004)'!J36) -> резерв | C10: ='SV777-2 (SV004)'!J37 | D10: =IF(B10="резерв","",'SV777-2 (SV004)'!L37) | E10: =IF('SV777-2 (SV004)'!L36<1,"","ШЛ."&'SV777-2 (SV004)'!L36)
A11: 8 | B11: =IF('SV777-2 (SV004)'!N36<1,"резерв",'SV777-2 (SV004)'!N36) -> резерв | C11: ='SV777-2 (SV004)'!N37 | D11: =IF(B11="резерв","",'SV777-2 (SV004)'!P37) | E11: =IF('SV777-2 (SV004)'!P36<1,"","ШЛ."&'SV777-2 (SV004)'!P36)
B12: SV004 - 2
A13: 1 | B13: =IF('SV777-2 (SV004)'!B58<1,"резерв",'SV777-2 (SV004)'!B58) -> резерв | C13: ='SV777-2 (SV004)'!B59 | D13: =IF(B13="резерв","",'SV777-2 (SV004)'!D59) | E13: =IF('SV777-2 (SV004)'!D58<1,"","ШЛ."&'SV777-2 (SV004)'!D58)
A14: 2 | B14: =IF('SV777-2 (SV004)'!F58<1,"резерв",'SV777-2 (SV004)'!F58) -> резерв | C14: ='SV777-2 (SV004)'!F59 | D14: =IF(B14="резерв","",'SV777-2 (SV004)'!H59) | E14: =IF('SV777-2 (SV004)'!H58<1,"","ШЛ."&'SV777-2 (SV004)'!H58)
A15: 3 | B15: =IF('SV777-2 (SV004)'!J58<1,"резерв",'SV777-2 (SV004)'!J58) -> резерв | C15: ='SV777-2 (SV004)'!J59 | D15: =IF(B15="резерв","",'SV777-2 (SV004)'!L59) | E15: =IF('SV777-2 (SV004)'!L58<1,"","ШЛ."&'SV777-2 (SV004)'!L58)
A16: 4 | B16: =IF('SV777-2 (SV004)'!N58<1,"резерв",'SV777-2 (SV004)'!N58) -> резерв | C16: ='SV777-2 (SV004)'!N59 | D16: =IF(B16="резерв","",'SV777-2 (SV004)'!P59) | E16: =IF('SV777-2 (SV004)'!P58<1,"","ШЛ."&'SV777-2 (SV004)'!P58)
A17: 5 | B17: =IF('SV777-2 (SV004)'!B78<1,"резерв",'SV777-2 (SV004)'!B78) -> резерв | C17: ='SV777-2 (SV004)'!B79 | D17: =IF(B17="резерв","",'SV777-2 (SV004)'!D79) | E17: =IF('SV777-2 (SV004)'!D78<1,"","ШЛ."&'SV777-2 (SV004)'!D78)
A18: 6 | B18: =IF('SV777-2 (SV004)'!F78<1,"резерв",'SV777-2 (SV004)'!F78) -> резерв | C18: ='SV777-2 (SV004)'!F79 | D18: =IF(B18="резерв","",'SV777-2 (SV004)'!H79) | E18: =IF('SV777-2 (SV004)'!H78<1,"","ШЛ."&'SV777-2 (SV004)'!H78)
A19: 7 | B19: =IF('SV777-2 (SV004)'!J78<1,"резерв",'SV777-2 (SV004)'!J78) -> резерв | C19: ='SV777-2 (SV004)'!J79 | D19: =IF(B19="резерв","",'SV777-2 (SV004)'!L79) | E19: =IF('SV777-2 (SV004)'!L78<1,"","ШЛ."&'SV777-2 (SV004)'!L78)
A20: 8 | B20: =IF('SV777-2 (SV004)'!N78<1,"резерв",'SV777-2 (SV004)'!N78) -> резерв | C20: ='SV777-2 (SV004)'!N79 | D20: =IF(B20="резерв","",'SV777-2 (SV004)'!P79) | E20: =IF('SV777-2 (SV004)'!P78<1,"","ШЛ."&'SV777-2 (SV004)'!P78)
B21: SV004 - 3
A22: 1 | B22: =IF('SV777-2 (SV004)'!B100<1,"резерв",'SV777-2 (SV004)'!B100) -> резерв | C22: ='SV777-2 (SV004)'!B101 | D22: =IF(B22="резерв","",'SV777-2 (SV004)'!D101) | E22: =IF('SV777-2 (SV004)'!D100<1,"","ШЛ."&'SV777-2 (SV004)'!D100)
A23: 2 | B23: =IF('SV777-2 (SV004)'!F100<1,"резерв",'SV777-2 (SV004)'!F100) -> резерв | C23: ='SV777-2 (SV004)'!F101 | D23: =IF(B23="резерв","",'SV777-2 (SV004)'!H101) | E23: =IF('SV777-2 (SV004)'!H100<1,"","ШЛ."&'SV777-2 (SV004)'!H100)
A24: 3 | B24: =IF('SV777-2 (SV004)'!J100<1,"резерв",'SV777-2 (SV004)'!J100) -> резерв | C24: ='SV777-2 (SV004)'!J101 | D24: =IF(B24="резерв","",'SV777-2 (SV004)'!L101) | E24: =IF('SV777-2 (SV004)'!L100<1,"","ШЛ."&'SV777-2 (SV004)'!L100)
A25: 4 | B25: =IF('SV777-2 (SV004)'!N100<1,"резерв",'SV777-2 (SV004)'!N100) -> резерв | C25: ='SV777-2 (SV004)'!N101 | D25: =IF(B25="резерв","",'SV777-2 (SV004)'!P101) | E25: =IF('SV777-2 (SV004)'!P100<1,"","ШЛ."&'SV777-2 (SV004)'!P100)
A26: 5 | B26: =IF('SV777-2 (SV004)'!B120<1,"резерв",'SV777-2 (SV004)'!B120) -> резерв | C26: ='SV777-2 (SV004)'!B121 | D26: =IF(B26="резерв","",'SV777-2 (SV004)'!D121) | E26: =IF('SV777-2 (SV004)'!D120<1,"","ШЛ."&'SV777-2 (SV004)'!D120)
A27: 6 | B27: =IF('SV777-2 (SV004)'!F120<1,"резерв",'SV777-2 (SV004)'!F120) -> резерв | C27: ='SV777-2 (SV004)'!F121 | D27: =IF(B27="резерв","",'SV777-2 (SV004)'!H121) | E27: =IF('SV777-2 (SV004)'!H120<1,"","ШЛ."&'SV777-2 (SV004)'!H120)
A28: 7 | B28: =IF('SV777-2 (SV004)'!J120<1,"резерв",'SV777-2 (SV004)'!J120) -> резерв | C28: ='SV777-2 (SV004)'!J121 | D28: =IF(B28="резерв","",'SV777-2 (SV004)'!L121) | E28: =IF('SV777-2 (SV004)'!L120<1,"","ШЛ."&'SV777-2 (SV004)'!L120)
A29: 8 | B29: =IF('SV777-2 (SV004)'!N120<1,"резерв",'SV777-2 (SV004)'!N120) -> резерв | C29: ='SV777-2 (SV004)'!N121 | D29: =IF(B29="резерв","",'SV777-2 (SV004)'!P121) | E29: =IF('SV777-2 (SV004)'!P120<1,"","ШЛ."&'SV777-2 (SV004)'!P120)
B30: SV004 - 4
A31: 1 | B31: =IF('SV777-2 (SV004)'!B142<1,"резерв",'SV777-2 (SV004)'!B142) -> резерв | C31: ='SV777-2 (SV004)'!B143 | D31: =IF(B31="резерв","",'SV777-2 (SV004)'!D143) | E31: =IF('SV777-2 (SV004)'!D142<1,"","ШЛ."&'SV777-2 (SV004)'!D142)
A32: 2 | B32: =IF('SV777-2 (SV004)'!F142<1,"резерв",'SV777-2 (SV004)'!F142) -> резерв | C32: ='SV777-2 (SV004)'!F143 | D32: =IF(B32="резерв","",'SV777-2 (SV004)'!H143) | E32: =IF('SV777-2 (SV004)'!H142<1,"","ШЛ."&'SV777-2 (SV004)'!H142)
A33: 3 | B33: =IF('SV777-2 (SV004)'!J142<1,"резерв",'SV777-2 (SV004)'!J142) -> резерв | C33: ='SV777-2 (SV004)'!J143 | D33: =IF(B33="резерв","",'SV777-2 (SV004)'!L143) | E33: =IF('SV777-2 (SV004)'!L142<1,"","ШЛ."&'SV777-2 (SV004)'!L142)
A34: 4 | B34: =IF('SV777-2 (SV004)'!N142<1,"резерв",'SV777-2 (SV004)'!N142) -> резерв | C34: ='SV777-2 (SV004)'!N143 | D34: =IF(B34="резерв","",'SV777-2 (SV004)'!P143) | E34: =IF('SV777-2 (SV004)'!P142<1,"","ШЛ."&'SV777-2 (SV004)'!P142)
A35: 5 | B35: =IF('SV777-2 (SV004)'!B162<1,"резерв",'SV777-2 (SV004)'!B162) -> резерв | C35: ='SV777-2 (SV004)'!B163 | D35: =IF(B35="резерв","",'SV777-2 (SV004)'!D163) | E35: =IF('SV777-2 (SV004)'!D162<1,"","ШЛ."&'SV777-2 (SV004)'!D162)
A36: 6 | B36: =IF('SV777-2 (SV004)'!F162<1,"резерв",'SV777-2 (SV004)'!F162) -> резерв | C36: ='SV777-2 (SV004)'!F163 | D36: =IF(B36="резерв","",'SV777-2 (SV004)'!H163) | E36: =IF('SV777-2 (SV004)'!H162<1,"","ШЛ."&'SV777-2 (SV004)'!H162)
A37: 7 | B37: =IF('SV777-2 (SV004)'!J162<1,"резерв",'SV777-2 (SV004)'!J162) -> резерв | C37: ='SV777-2 (SV004)'!J163 | D37: =IF(B37="резерв","",'SV777-2 (SV004)'!L163) | E37: =IF('SV777-2 (SV004)'!L162<1,"","ШЛ."&'SV777-2 (SV004)'!L162)
A38: 8 | B38: =IF('SV777-2 (SV004)'!N162<1,"резерв",'SV777-2 (SV004)'!N162) -> резерв | C38: ='SV777-2 (SV004)'!N163 | D38: =IF(B38="резерв","",'SV777-2 (SV004)'!P163) | E38: =IF('SV777-2 (SV004)'!P162<1,"","ШЛ."&'SV777-2 (SV004)'!P162)
B39: SV004 - 5
A40: 1 | B40: =IF('SV777-2 (SV004)'!B184<1,"резерв",'SV777-2 (SV004)'!B184) -> резерв | C40: ='SV777-2 (SV004)'!B185 | D40: =IF(B40="резерв","",'SV777-2 (SV004)'!D185) | E40: =IF('SV777-2 (SV004)'!D184<1,"","ШЛ."&'SV777-2 (SV004)'!D184)
A41: 2 | B41: =IF('SV777-2 (SV004)'!F184<1,"резерв",'SV777-2 (SV004)'!F184) -> резерв | C41: ='SV777-2 (SV004)'!F185 | D41: =IF(B41="резерв","",'SV777-2 (SV004)'!H185) | E41: =IF('SV777-2 (SV004)'!H184<1,"","ШЛ."&'SV777-2 (SV004)'!H184)
...

Sheet шпоргалка-3
C2: SV777 - 3
B3: SV004 - 1
A4: 1 | B4: =IF('SV777-3 (SV004)'!B16<1,"резерв",'SV777-3 (SV004)'!B16) -> резерв | C4: ='SV777-3 (SV004)'!B17 | D4: =IF(B4="резерв","",'SV777-3 (SV004)'!D17) | E4: =IF('SV777-3 (SV004)'!D16<1,"","ШЛ."&'SV777-3 (SV004)'!D16)
A5: 2 | B5: =IF('SV777-3 (SV004)'!F16<1,"резерв",'SV777-3 (SV004)'!F16) -> резерв | C5: ='SV777-3 (SV004)'!F17 | D5: =IF(B5="резерв","",'SV777-3 (SV004)'!H17) | E5: =IF('SV777-3 (SV004)'!H16<1,"","ШЛ."&'SV777-3 (SV004)'!H16)
A6: 3 | B6: =IF('SV777-3 (SV004)'!J16<1,"резерв",'SV777-3 (SV004)'!J16) -> резерв | C6: ='SV777-3 (SV004)'!J17 | D6: =IF(B6="резерв","",'SV777-3 (SV004)'!L17) | E6: =IF('SV777-3 (SV004)'!L16<1,"","ШЛ."&'SV777-3 (SV004)'!L16)
A7: 4 | B7: =IF('SV777-3 (SV004)'!N16<1,"резерв",'SV777-3 (SV004)'!N16) -> резерв | C7: ='SV777-3 (SV004)'!N17 | D7: =IF(B7="резерв","",'SV777-3 (SV004)'!P17) | E7: =IF('SV777-3 (SV004)'!P16<1,"","ШЛ."&'SV777-3 (SV004)'!P16)
A8: 5 | B8: =IF('SV777-3 (SV004)'!B36<1,"резерв",'SV777-3 (SV004)'!B36) -> резерв | C8: ='SV777-3 (SV004)'!B37 | D8: =IF(B8="резерв","",'SV777-3 (SV004)'!D37) | E8: =IF('SV777-3 (SV004)'!D36<1,"","ШЛ."&'SV777-3 (SV004)'!D36)
A9: 6 | B9: =IF('SV777-3 (SV004)'!F36<1,"резерв",'SV777-3 (SV004)'!F36) -> резерв | C9: ='SV777-3 (SV004)'!F37 | D9: =IF(B9="резерв","",'SV777-3 (SV004)'!H37) | E9: =IF('SV777-3 (SV004)'!H36<1,"","ШЛ."&'SV777-3 (SV004)'!H36)
A10: 7 | B10: =IF('SV777-3 (SV004)'!J36<1,"резерв",'SV777-3 (SV004)'!J36) -> резерв | C10: ='SV777-3 (SV004)'!J37 | D10: =IF(B10="резерв","",'SV777-3 (SV004)'!L37) | E10: =IF('SV777-3 (SV004)'!L36<1,"","ШЛ."&'SV777-3 (SV004)'!L36)
A11: 8 | B11: =IF('SV777-3 (SV004)'!N36<1,"резерв",'SV777-3 (SV004)'!N36) -> резерв | C11: ='SV777-3 (SV004)'!N37 | D11: =IF(B11="резерв","",'SV777-3 (SV004)'!P37) | E11: =IF('SV777-3 (SV004)'!P36<1,"","ШЛ."&'SV777-3 (SV004)'!P36)
B12: SV004 - 2
A13: 1 | B13: =IF('SV777-3 (SV004)'!B58<1,"резерв",'SV777-3 (SV004)'!B58) -> резерв | C13: ='SV777-3 (SV004)'!B59 | D13: =IF(B13="резерв","",'SV777-3 (SV004)'!D59) | E13: =IF('SV777-3 (SV004)'!D58<1,"","ШЛ."&'SV777-3 (SV004)'!D58)
A14: 2 | B14: =IF('SV777-3 (SV004)'!F58<1,"резерв",'SV777-3 (SV004)'!F58) -> резерв | C14: ='SV777-3 (SV004)'!F59 | D14: =IF(B14="резерв","",'SV777-3 (SV004)'!H59) | E14: =IF('SV777-3 (SV004)'!H58<1,"","ШЛ."&'SV777-3 (SV004)'!H58)
A15: 3 | B15: =IF('SV777-3 (SV004)'!J58<1,"резерв",'SV777-3 (SV004)'!J58) -> резерв | C15: ='SV777-3 (SV004)'!J59 | D15: =IF(B15="резерв","",'SV777-3 (SV004)'!L59) | E15: =IF('SV777-3 (SV004)'!L58<1,"","ШЛ."&'SV777-3 (SV004)'!L58)
A16: 4 | B16: =IF('SV777-3 (SV004)'!N58<1,"резерв",'SV777-3 (SV004)'!N58) -> резерв | C16: ='SV777-3 (SV004)'!N59 | D16: =IF(B16="резерв","",'SV777-3 (SV004)'!P59) | E16: =IF('SV777-3 (SV004)'!P58<1,"","ШЛ."&'SV777-3 (SV004)'!P58)
A17: 5 | B17: =IF('SV777-3 (SV004)'!B78<1,"резерв",'SV777-3 (SV004)'!B78) -> резерв | C17: ='SV777-3 (SV004)'!B79 | D17: =IF(B17="резерв","",'SV777-3 (SV004)'!D79) | E17: =IF('SV777-3 (SV004)'!D78<1,"","ШЛ."&'SV777-3 (SV004)'!D78)
A18: 6 | B18: =IF('SV777-3 (SV004)'!F78<1,"резерв",'SV777-3 (SV004)'!F78) -> резерв | C18: ='SV777-3 (SV004)'!F79 | D18: =IF(B18="резерв","",'SV777-3 (SV004)'!H79) | E18: =IF('SV777-3 (SV004)'!H78<1,"","ШЛ."&'SV777-3 (SV004)'!H78)
A19: 7 | B19: =IF('SV777-3 (SV004)'!J78<1,"резерв",'SV777-3 (SV004)'!J78) -> резерв | C19: ='SV777-3 (SV004)'!J79 | D19: =IF(B19="резерв","",'SV777-3 (SV004)'!L79) | E19: =IF('SV777-3 (SV004)'!L78<1,"","ШЛ."&'SV777-3 (SV004)'!L78)
A20: 8 | B20: =IF('SV777-3 (SV004)'!N78<1,"резерв",'SV777-3 (SV004)'!N78) -> резерв | C20: ='SV777-3 (SV004)'!N79 | D20: =IF(B20="резерв","",'SV777-3 (SV004)'!P79) | E20: =IF('SV777-3 (SV004)'!P78<1,"","ШЛ."&'SV777-3 (SV004)'!P78)
B21: SV004 - 3
A22: 1 | B22: =IF('SV777-3 (SV004)'!B100<1,"резерв",'SV777-3 (SV004)'!B100) -> резерв | C22: ='SV777-3 (SV004)'!B101 | D22: =IF(B22="резерв","",'SV777-3 (SV004)'!D101) | E22: =IF('SV777-3 (SV004)'!D100<1,"","ШЛ."&'SV777-3 (SV004)'!D100)
A23: 2 | B23: =IF('SV777-3 (SV004)'!F100<1,"резерв",'SV777-3 (SV004)'!F100) -> резерв | C23: ='SV777-3 (SV004)'!F101 | D23: =IF(B23="резерв","",'SV777-3 (SV004)'!H101) | E23: =IF('SV777-3 (SV004)'!H100<1,"","ШЛ."&'SV777-3 (SV004)'!H100)
A24: 3 | B24: =IF('SV777-3 (SV004)'!J100<1,"резерв",'SV777-3 (SV004)'!J100) -> резерв | C24: ='SV777-3 (SV004)'!J101 | D24: =IF(B24="резерв","",'SV777-3 (SV004)'!L101) | E24: =IF('SV777-3 (SV004)'!L100<1,"","ШЛ."&'SV777-3 (SV004)'!L100)
A25: 4 | B25: =IF('SV777-3 (SV004)'!N100<1,"резерв",'SV777-3 (SV004)'!N100) -> резерв | C25: ='SV777-3 (SV004)'!N101 | D25: =IF(B25="резерв","",'SV777-3 (SV004)'!P101) | E25: =IF('SV777-3 (SV004)'!P100<1,"","ШЛ."&'SV777-3 (SV004)'!P100)
A26: 5 | B26: =IF('SV777-3 (SV004)'!B120<1,"резерв",'SV777-3 (SV004)'!B120) -> резерв | C26: ='SV777-3 (SV004)'!B121 | D26: =IF(B26="резерв","",'SV777-3 (SV004)'!D121) | E26: =IF('SV777-3 (SV004)'!D120<1,"","ШЛ."&'SV777-3 (SV004)'!D120)
A27: 6 | B27: =IF('SV777-3 (SV004)'!F120<1,"резерв",'SV777-3 (SV004)'!F120) -> резерв | C27: ='SV777-3 (SV004)'!F121 | D27: =IF(B27="резерв","",'SV777-3 (SV004)'!H121) | E27: =IF('SV777-3 (SV004)'!H120<1,"","ШЛ."&'SV777-3 (SV004)'!H120)
A28: 7 | B28: =IF('SV777-3 (SV004)'!J120<1,"резерв",'SV777-3 (SV004)'!J120) -> резерв | C28: ='SV777-3 (SV004)'!J121 | D28: =IF(B28="резерв","",'SV777-3 (SV004)'!L121) | E28: =IF('SV777-3 (SV004)'!L120<1,"","ШЛ."&'SV777-3 (SV004)'!L120)
A29: 8 | B29: =IF('SV777-3 (SV004)'!N120<1,"резерв",'SV777-3 (SV004)'!N120) -> резерв | C29: ='SV777-3 (SV004)'!N121 | D29: =IF(B29="резерв","",'SV777-3 (SV004)'!P121) | E29: =IF('SV777-3 (SV004)'!P120<1,"","ШЛ."&'SV777-3 (SV004)'!P120)
B30: SV004 - 4
A31: 1 | B31: =IF('SV777-3 (SV004)'!B142<1,"резерв",'SV777-3 (SV004)'!B142) -> резерв | C31: ='SV777-3 (SV004)'!B143 | D31: =IF(B31="резерв","",'SV777-3 (SV004)'!D143) | E31: =IF('SV777-3 (SV004)'!D142<1,"","ШЛ."&'SV777-3 (SV004)'!D142)
A32: 2 | B32: =IF('SV777-3 (SV004)'!F142<1,"резерв",'SV777-3 (SV004)'!F142) -> резерв | C32: ='SV777-3 (SV004)'!F143 | D32: =IF(B32="резерв","",'SV777-3 (SV004)'!H143) | E32: =IF('SV777-3 (SV004)'!H142<1,"","ШЛ."&'SV777-3 (SV004)'!H142)
A33: 3 | B33: =IF('SV777-3 (SV004)'!J142<1,"резерв",'SV777-3 (SV004)'!J142) -> резерв | C33: ='SV777-3 (SV004)'!J143 | D33: =IF(B33="резерв","",'SV777-3 (SV004)'!L143) | E33: =IF('SV777-3 (SV004)'!L142<1,"","ШЛ."&'SV777-3 (SV004)'!L142)
A34: 4 | B34: =IF('SV777-3 (SV004)'!N142<1,"резерв",'SV777-3 (SV004)'!N142) -> резерв | C34: ='SV777-3 (SV004)'!N143 | D34: =IF(B34="резерв","",'SV777-3 (SV004)'!P143) | E34: =IF('SV777-3 (SV004)'!P142<1,"","ШЛ."&'SV777-3 (SV004)'!P142)
A35: 5 | B35: =IF('SV777-3 (SV004)'!B162<1,"резерв",'SV777-3 (SV004)'!B162) -> резерв | C35: ='SV777-3 (SV004)'!B163 | D35: =IF(B35="резерв","",'SV777-3 (SV004)'!D163) | E35: =IF('SV777-3 (SV004)'!D162<1,"","ШЛ."&'SV777-3 (SV004)'!D162)
A36: 6 | B36: =IF('SV777-3 (SV004)'!F162<1,"резерв",'SV777-3 (SV004)'!F162) -> резерв | C36: ='SV777-3 (SV004)'!F163 | D36: =IF(B36="резерв","",'SV777-3 (SV004)'!H163) | E36: =IF('SV777-3 (SV004)'!H162<1,"","ШЛ."&'SV777-3 (SV004)'!H162)
A37: 7 | B37: =IF('SV777-3 (SV004)'!J162<1,"резерв",'SV777-3 (SV004)'!J162) -> резерв | C37: ='SV777-3 (SV004)'!J163 | D37: =IF(B37="резерв","",'SV777-3 (SV004)'!L163) | E37: =IF('SV777-3 (SV004)'!L162<1,"","ШЛ."&'SV777-3 (SV004)'!L162)
A38: 8 | B38: =IF('SV777-3 (SV004)'!N162<1,"резерв",'SV777-3 (SV004)'!N162) -> резерв | C38: ='SV777-3 (SV004)'!N163 | D38: =IF(B38="резерв","",'SV777-3 (SV004)'!P163) | E38: =IF('SV777-3 (SV004)'!P162<1,"","ШЛ."&'SV777-3 (SV004)'!P162)
B39: SV004 - 5
A40: 1 | B40: =IF('SV777-3 (SV004)'!B184<1,"резерв",'SV777-3 (SV004)'!B184) -> резерв | C40: ='SV777-3 (SV004)'!B185 | D40: =IF(B40="резерв","",'SV777-3 (SV004)'!D185) | E40: =IF('SV777-3 (SV004)'!D184<1,"","ШЛ."&'SV777-3 (SV004)'!D184)
A41: 2 | B41: =IF('SV777-3 (SV004)'!F184<1,"резерв",'SV777-3 (SV004)'!F184) -> резерв | C41: ='SV777-3 (SV004)'!F185 | D41: =IF(B41="резерв","",'SV777-3 (SV004)'!H185) | E41: =IF('SV777-3 (SV004)'!H184<1,"","ШЛ."&'SV777-3 (SV004)'!H184)
...

Sheet Шпоргалка общая
C2: ='шпоргалка-1'!C2 -> SV777 - 1 | I2: ='шпоргалка-2'!C2 -> SV777 - 2 | O2: ='шпоргалка-3'!C2 -> SV777 - 3
B3: ='шпоргалка-1'!B3 -> SV004 -1 | H3: ='шпоргалка-2'!B3 -> SV004 - 1 | N3: ='шпоргалка-3'!B3 -> SV004 - 1
A4: ='шпоргалка-1'!A4 -> 1 | B4: ='шпоргалка-1'!B4 -> резерв | C4: ='шпоргалка-1'!C4 -> 0 | D4: ='шпоргалка-1'!D4 | E4: ='шпоргалка-1'!E4 | G4: ='шпоргалка-2'!A4 -> 1 | H4: ='шпоргалка-2'!B4 -> резерв | I4: ='шпоргалка-2'!C4 -> 0 | J4: ='шпоргалка-2'!D4 | K4: ='шпоргалка-2'!E4 | M4: ='шпоргалка-3'!A4 -> 1 | N4: ='шпоргалка-3'!B4 -> резерв | O4: ='шпоргалка-3'!C4 | P4: ='шпоргалка-3'!D4 | Q4: ='шпоргалка-3'!E4
A5: ='шпоргалка-1'!A5 -> 2 | B5: ='шпоргалка-1'!B5 -> резерв | C5: ='шпоргалка-1'!C5 -> 0 | D5: ='шпоргалка-1'!D5 | E5: ='шпоргалка-1'!E5 | G5: ='шпоргалка-2'!A5 -> 2 | H5: ='шпоргалка-2'!B5 -> резерв | I5: ='шпоргалка-2'!C5 | J5: ='шпоргалка-2'!D5 | K5: ='шпоргалка-2'!E5 | M5: ='шпоргалка-3'!A5 -> 2 | N5: ='шпоргалка-3'!B5 -> резерв | O5: ='шпоргалка-3'!C5 | P5: ='шпоргалка-3'!D5 | Q5: ='шпоргалка-3'!E5
A6: ='шпоргалка-1'!A6 -> 3 | B6: ='шпоргалка-1'!B6 -> резерв | C6: ='шпоргалка-1'!C6 -> 0 | D6: ='шпоргалка-1'!D6 | E6: ='шпоргалка-1'!E6 | G6: ='шпоргалка-2'!A6 -> 3 | H6: ='шпоргалка-2'!B6 -> резерв | I6: ='шпоргалка-2'!C6 | J6: ='шпоргалка-2'!D6 | K6: ='шпоргалка-2'!E6 | M6: ='шпоргалка-3'!A6 -> 3 | N6: ='шпоргалка-3'!B6 -> резерв | O6: ='шпоргалка-3'!C6 | P6: ='шпоргалка-3'!D6 | Q6: ='шпоргалка-3'!E6
A7: ='шпоргалка-1'!A7 -> 4 | B7: ='шпоргалка-1'!B7 -> резерв | C7: ='шпоргалка-1'!C7 -> 0 | D7: ='шпоргалка-1'!D7 | E7: ='шпоргалка-1'!E7 | G7: ='шпоргалка-2'!A7 -> 4 | H7: ='шпоргалка-2'!B7 -> резерв | I7: ='шпоргалка-2'!C7 | J7: ='шпоргалка-2'!D7 | K7: ='шпоргалка-2'!E7 | M7: ='шпоргалка-3'!A7 -> 4 | N7: ='шпоргалка-3'!B7 -> резерв | O7: ='шпоргалка-3'!C7 | P7: ='шпоргалка-3'!D7 | Q7: ='шпоргалка-3'!E7
A8: ='шпоргалка-1'!A8 -> 5 | B8: ='шпоргалка-1'!B8 -> #REF! | C8: ='шпоргалка-1'!C8 -> #REF! | D8: ='шпоргалка-1'!D8 -> #REF! | E8: ='шпоргалка-1'!E8 -> #REF! | G8: ='шпоргалка-2'!A8 -> 5 | H8: ='шпоргалка-2'!B8 -> резерв | I8: ='шпоргалка-2'!C8 | J8: ='шпоргалка-2'!D8 | K8: ='шпоргалка-2'!E8 | M8: ='шпоргалка-3'!A8 -> 5 | N8: ='шпоргалка-3'!B8 -> резерв | O8: ='шпоргалка-3'!C8 | P8: ='шпоргалка-3'!D8 | Q8: ='шпоргалка-3'!E8
A9: ='шпоргалка-1'!A9 -> 6 | B9: ='шпоргалка-1'!B9 -> #REF! | C9: ='шпоргалка-1'!C9 -> #REF! | D9: ='шпоргалка-1'!D9 -> #REF! | E9: ='шпоргалка-1'!E9 -> #REF! | G9: ='шпоргалка-2'!A9 -> 6 | H9: ='шпоргалка-2'!B9 -> резерв | I9: ='шпоргалка-2'!C9 | J9: ='шпоргалка-2'!D9 | K9: ='шпоргалка-2'!E9 | M9: ='шпоргалка-3'!A9 -> 6 | N9: ='шпоргалка-3'!B9 -> резерв | O9: ='шпоргалка-3'!C9 | P9: ='шпоргалка-3'!D9 | Q9: ='шпоргалка-3'!E9
A10: ='шпоргалка-1'!A10 -> 7 | B10: ='шпоргалка-1'!B10 -> #REF! | C10: ='шпоргалка-1'!C10 -> #REF! | D10: ='шпоргалка-1'!D10 -> #REF! | E10: ='шпоргалка-1'!E10 -> #REF! | G10: ='шпоргалка-2'!A10 -> 7 | H10: ='шпоргалка-2'!B10 -> резерв | I10: ='шпоргалка-2'!C10 | J10: ='шпоргалка-2'!D10 | K10: ='шпоргалка-2'!E10 | M10: ='шпоргалка-3'!A10 -> 7 | N10: ='шпоргалка-3'!B10 -> резерв | O10: ='шпоргалка-3'!C10 | P10: ='шпоргалка-3'!D10 | Q10: ='шпоргалка-3'!E10
A11: ='шпоргалка-1'!A11 -> 8 | B11: ='шпоргалка-1'!B11 -> #REF! | C11: ='шпоргалка-1'!C11 -> #REF! | D11: ='шпоргалка-1'!D11 -> #REF! | E11: ='шпоргалка-1'!E11 -> #REF! | G11: ='шпоргалка-2'!A11 -> 8 | H11: ='шпоргалка-2'!B11 -> резерв | I11: ='шпоргалка-2'!C11 | J11: ='шпоргалка-2'!D11 | K11: ='шпоргалка-2'!E11 | M11: ='шпоргалка-3'!A11 -> 8 | N11: ='шпоргалка-3'!B11 -> резерв | O11: ='шпоргалка-3'!C11 | P11: ='шпоргалка-3'!D11 | Q11: ='шпоргалка-3'!E11
B12: ='шпоргалка-1'!B12 -> SV004 - 2 | H12: ='шпоргалка-2'!B12 -> SV004 - 2 | N12: ='шпоргалка-3'!B12 -> SV004 - 2
A13: ='шпоргалка-1'!A13 -> 1 | B13: ='шпоргалка-1'!B13 -> #REF! | C13: ='шпоргалка-1'!C13 -> #REF! | D13: ='шпоргалка-1'!D13 -> #REF! | E13: ='шпоргалка-1'!E13 -> #REF! | G13: ='шпоргалка-2'!A13 -> 1 | H13: ='шпоргалка-2'!B13 -> резерв | I13: ='шпоргалка-2'!C13 | J13: ='шпоргалка-2'!D13 | K13: ='шпоргалка-2'!E13 | M13: ='шпоргалка-3'!A13 -> 1 | N13: ='шпоргалка-3'!B13 -> резерв | O13: ='шпоргалка-3'!C13 | P13: ='шпоргалка-3'!D13 | Q13: ='шпоргалка-3'!E13
A14: ='шпоргалка-1'!A14 -> 2 | B14: ='шпоргалка-1'!B14 -> #REF! | C14: ='шпоргалка-1'!C14 -> #REF! | D14: ='шпоргалка-1'!D14 -> #REF! | E14: ='шпоргалка-1'!E14 -> #REF! | G14: ='шпоргалка-2'!A14 -> 2 | H14: ='шпоргалка-2'!B14 -> резерв | I14: ='шпоргалка-2'!C14 | J14: ='шпоргалка-2'!D14 | K14: ='шпоргалка-2'!E14 | M14: ='шпоргалка-3'!A14 -> 2 | N14: ='шпоргалка-3'!B14 -> резерв | O14: ='шпоргалка-3'!C14 | P14: ='шпоргалка-3'!D14 | Q14: ='шпоргалка-3'!E14
A15: ='шпоргалка-1'!A15 -> 3 | B15: ='шпоргалка-1'!B15 -> #REF! | C15: ='шпоргалка-1'!C15 -> #REF! | D15: ='шпоргалка-1'!D15 -> #REF! | E15: ='шпоргалка-1'!E15 -> #REF! | G15: ='шпоргалка-2'!A15 -> 3 | H15: ='шпоргалка-2'!B15 -> резерв | I15: ='шпоргалка-2'!C15 | J15: ='шпоргалка-2'!D15 | K15: ='шпоргалка-2'!E15 | M15: ='шпоргалка-3'!A15 -> 3 | N15: ='шпоргалка-3'!B15 -> резерв | O15: ='шпоргалка-3'!C15 | P15: ='шпоргалка-3'!D15 | Q15: ='шпоргалка-3'!E15
A16: ='шпоргалка-1'!A16 -> 4 | B16: ='шпоргалка-1'!B16 -> #REF! | C16: ='шпоргалка-1'!C16 -> #REF! | D16: ='шпоргалка-1'!D16 -> #REF! | E16: ='шпоргалка-1'!E16 -> #REF! | G16: ='шпоргалка-2'!A16 -> 4 | H16: ='шпоргалка-2'!B16 -> резерв | I16: ='шпоргалка-2'!C16 | J16: ='шпоргалка-2'!D16 | K16: ='шпоргалка-2'!E16 | M16: ='шпоргалка-3'!A16 -> 4 | N16: ='шпоргалка-3'!B16 -> резерв | O16: ='шпоргалка-3'!C16 | P16: ='шпоргалка-3'!D16 | Q16: ='шпоргалка-3'!E16
A17: ='шпоргалка-1'!A17 -> 5 | B17: ='шпоргалка-1'!B17 -> #REF! | C17: ='шпоргалка-1'!C17 -> #REF! | D17: ='шпоргалка-1'!D17 -> #REF! | E17: ='шпоргалка-1'!E17 -> #REF! | G17: ='шпоргалка-2'!A17 -> 5 | H17: ='шпоргалка-2'!B17 -> резерв | I17: ='шпоргалка-2'!C17 | J17: ='шпоргалка-2'!D17 | K17: ='шпоргалка-2'!E17 | M17: ='шпоргалка-3'!A17 -> 5 | N17: ='шпоргалка-3'!B17 -> резерв | O17: ='шпоргалка-3'!C17 | P17: ='шпоргалка-3'!D17 | Q17: ='шпоргалка-3'!E17
A18: ='шпоргалка-1'!A18 -> 6 | B18: ='шпоргалка-1'!B18 -> #REF! | C18: ='шпоргалка-1'!C18 -> #REF! | D18: ='шпоргалка-1'!D18 -> #REF! | E18: ='шпоргалка-1'!E18 -> #REF! | G18: ='шпоргалка-2'!A18 -> 6 | H18: ='шпоргалка-2'!B18 -> резерв | I18: ='шпоргалка-2'!C18 | J18: ='шпоргалка-2'!D18 | K18: ='шпоргалка-2'!E18 | M18: ='шпоргалка-3'!A18 -> 6 | N18: ='шпоргалка-3'!B18 -> резерв | O18: ='шпоргалка-3'!C18 | P18: ='шпоргалка-3'!D18 | Q18: ='шпоргалка-3'!E18
A19: ='шпоргалка-1'!A19 -> 7 | B19: ='шпоргалка-1'!B19 -> #REF! | C19: ='шпоргалка-1'!C19 -> #REF! | D19: ='шпоргалка-1'!D19 -> #REF! | E19: ='шпоргалка-1'!E19 -> #REF! | G19: ='шпоргалка-2'!A19 -> 7 | H19: ='шпоргалка-2'!B19 -> резерв | I19: ='шпоргалка-2'!C19 | J19: ='шпоргалка-2'!D19 | K19: ='шпоргалка-2'!E19 | M19: ='шпоргалка-3'!A19 -> 7 | N19: ='шпоргалка-3'!B19 -> резерв | O19: ='шпоргалка-3'!C19 | P19: ='шпоргалка-3'!D19 | Q19: ='шпоргалка-3'!E19
A20: ='шпоргалка-1'!A20 -> 8 | B20: ='шпоргалка-1'!B20 -> #REF! | C20: ='шпоргалка-1'!C20 -> #REF! | D20: ='шпоргалка-1'!D20 -> #REF! | E20: ='шпоргалка-1'!E20 -> #REF! | G20: ='шпоргалка-2'!A20 -> 8 | H20: ='шпоргалка-2'!B20 -> резерв | I20: ='шпоргалка-2'!C20 | J20: ='шпоргалка-2'!D20 | K20: ='шпоргалка-2'!E20 | M20: ='шпоргалка-3'!A20 -> 8 | N20: ='шпоргалка-3'!B20 -> резерв | O20: ='шпоргалка-3'!C20 | P20: ='шпоргалка-3'!D20 | Q20: ='шпоргалка-3'!E20
B21: ='шпоргалка-1'!B21 -> SV004 - 3 | H21: ='шпоргалка-2'!B21 -> SV004 - 3 | N21: ='шпоргалка-3'!B21 -> SV004 - 3
A22: ='шпоргалка-1'!A22 -> 1 | B22: ='шпоргалка-1'!B22 -> #REF! | C22: ='шпоргалка-1'!C22 -> #REF! | D22: ='шпоргалка-1'!D22 -> #REF! | E22: ='шпоргалка-1'!E22 -> #REF! | G22: ='шпоргалка-2'!A22 -> 1 | H22: ='шпоргалка-2'!B22 -> резерв | I22: ='шпоргалка-2'!C22 | J22: ='шпоргалка-2'!D22 | K22: ='шпоргалка-2'!E22 | M22: ='шпоргалка-3'!A22 -> 1 | N22: ='шпоргалка-3'!B22 -> резерв | O22: ='шпоргалка-3'!C22 | P22: ='шпоргалка-3'!D22 | Q22: ='шпоргалка-3'!E22
A23: ='шпоргалка-1'!A23 -> 2 | B23: ='шпоргалка-1'!B23 -> #REF! | C23: ='шпоргалка-1'!C23 -> #REF! | D23: ='шпоргалка-1'!D23 -> #REF! | E23: ='шпоргалка-1'!E23 -> #REF! | G23: ='шпоргалка-2'!A23 -> 2 | H23: ='шпоргалка-2'!B23 -> резерв | I23: ='шпоргалка-2'!C23 | J23: ='шпоргалка-2'!D23 | K23: ='шпоргалка-2'!E23 | M23: ='шпоргалка-3'!A23 -> 2 | N23: ='шпоргалка-3'!B23 -> резерв | O23: ='шпоргалка-3'!C23 | P23: ='шпоргалка-3'!D23 | Q23: ='шпоргалка-3'!E23
A24: ='шпоргалка-1'!A24 -> 3 | B24: ='шпоргалка-1'!B24 -> #REF! | C24: ='шпоргалка-1'!C24 -> #REF! | D24: ='шпоргалка-1'!D24 -> #REF! | E24: ='шпоргалка-1'!E24 -> #REF! | G24: ='шпоргалка-2'!A24 -> 3 | H24: ='шпоргалка-2'!B24 -> резерв | I24: ='шпоргалка-2'!C24 | J24: ='шпоргалка-2'!D24 | K24: ='шпоргалка-2'!E24 | M24: ='шпоргалка-3'!A24 -> 3 | N24: ='шпоргалка-3'!B24 -> резерв | O24: ='шпоргалка-3'!C24 | P24: ='шпоргалка-3'!D24 | Q24: ='шпоргалка-3'!E24
A25: ='шпоргалка-1'!A25 -> 4 | B25: ='шпоргалка-1'!B25 -> #REF! | C25: ='шпоргалка-1'!C25 -> #REF! | D25: ='шпоргалка-1'!D25 -> #REF! | E25: ='шпоргалка-1'!E25 -> #REF! | G25: ='шпоргалка-2'!A25 -> 4 | H25: ='шпоргалка-2'!B25 -> резерв | I25: ='шпоргалка-2'!C25 | J25: ='шпоргалка-2'!D25 | K25: ='шпоргалка-2'!E25 | M25: ='шпоргалка-3'!A25 -> 4 | N25: ='шпоргалка-3'!B25 -> резерв | O25: ='шпоргалка-3'!C25 | P25: ='шпоргалка-3'!D25 | Q25: ='шпоргалка-3'!E25
A26: ='шпоргалка-1'!A26 -> 5 | B26: ='шпоргалка-1'!B26 -> #REF! | C26: ='шпоргалка-1'!C26 -> #REF! | D26: ='шпоргалка-1'!D26 -> #REF! | E26: ='шпоргалка-1'!E26 -> #REF! | G26: ='шпоргалка-2'!A26 -> 5 | H26: ='шпоргалка-2'!B26 -> резерв | I26: ='шпоргалка-2'!C26 | J26: ='шпоргалка-2'!D26 | K26: ='шпоргалка-2'!E26 | M26: ='шпоргалка-3'!A26 -> 5 | N26: ='шпоргалка-3'!B26 -> резерв | O26: ='шпоргалка-3'!C26 | P26: ='шпоргалка-3'!D26 | Q26: ='шпоргалка-3'!E26
A27: ='шпоргалка-1'!A27 -> 6 | B27: ='шпоргалка-1'!B27 -> #REF! | C27: ='шпоргалка-1'!C27 -> #REF! | D27: ='шпоргалка-1'!D27 -> #REF! | E27: ='шпоргалка-1'!E27 -> #REF! | G27: ='шпоргалка-2'!A27 -> 6 | H27: ='шпоргалка-2'!B27 -> резерв | I27: ='шпоргалка-2'!C27 | J27: ='шпоргалка-2'!D27 | K27: ='шпоргалка-2'!E27 | M27: ='шпоргалка-3'!A27 -> 6 | N27: ='шпоргалка-3'!B27 -> резерв | O27: ='шпоргалка-3'!C27 | P27: ='шпоргалка-3'!D27 | Q27: ='шпоргалка-3'!E27
A28: ='шпоргалка-1'!A28 -> 7 | B28: ='шпоргалка-1'!B28 -> #REF! | C28: ='шпоргалка-1'!C28 -> #REF! | D28: ='шпоргалка-1'!D28 -> #REF! | E28: ='шпоргалка-1'!E28 -> #REF! | G28: ='шпоргалка-2'!A28 -> 7 | H28: ='шпоргалка-2'!B28 -> резерв | I28: ='шпоргалка-2'!C28 | J28: ='шпоргалка-2'!D28 | K28: ='шпоргалка-2'!E28 | M28: ='шпоргалка-3'!A28 -> 7 | N28: ='шпоргалка-3'!B28 -> резерв | O28: ='шпоргалка-3'!C28 | P28: ='шпоргалка-3'!D28 | Q28: ='шпоргалка-3'!E28
A29: ='шпоргалка-1'!A29 -> 8 | B29: ='шпоргалка-1'!B29 -> #REF! | C29: ='шпоргалка-1'!C29 -> #REF! | D29: ='шпоргалка-1'!D29 -> #REF! | E29: ='шпоргалка-1'!E29 -> #REF! | G29: ='шпоргалка-2'!A29 -> 8 | H29: ='шпоргалка-2'!B29 -> резерв | I29: ='шпоргалка-2'!C29 | J29: ='шпоргалка-2'!D29 | K29: ='шпоргалка-2'!E29 | M29: ='шпоргалка-3'!A29 -> 8 | N29: ='шпоргалка-3'!B29 -> резерв | O29: ='шпоргалка-3'!C29 | P29: ='шпоргалка-3'!D29 | Q29: ='шпоргалка-3'!E29
B30: ='шпоргалка-1'!B30 -> SV004 - 4 | H30: ='шпоргалка-2'!B30 -> SV004 - 4 | N30: ='шпоргалка-3'!B30 -> SV004 - 4
A31: ='шпоргалка-1'!A31 -> 1 | B31: ='шпоргалка-1'!B31 -> #REF! | C31: ='шпоргалка-1'!C31 -> #REF! | D31: ='шпоргалка-1'!D31 -> #REF! | E31: ='шпоргалка-1'!E31 -> #REF! | G31: ='шпоргалка-2'!A31 -> 1 | H31: ='шпоргалка-2'!B31 -> резерв | I31: ='шпоргалка-2'!C31 | J31: ='шпоргалка-2'!D31 | K31: ='шпоргалка-2'!E31 | M31: ='шпоргалка-3'!A31 -> 1 | N31: ='шпоргалка-3'!B31 -> резерв | O31: ='шпоргалка-3'!C31 | P31: ='шпоргалка-3'!D31 | Q31: ='шпоргалка-3'!E31
A32: ='шпоргалка-1'!A32 -> 2 | B32: ='шпоргалка-1'!B32 -> #REF! | C32: ='шпоргалка-1'!C32 -> #REF! | D32: ='шпоргалка-1'!D32 -> #REF! | E32: ='шпоргалка-1'!E32 -> #REF! | G32: ='шпоргалка-2'!A32 -> 2 | H32: ='шпоргалка-2'!B32 -> резерв | I32: ='шпоргалка-2'!C32 | J32: ='шпоргалка-2'!D32 | K32: ='шпоргалка-2'!E32 | M32: ='шпоргалка-3'!A32 -> 2 | N32: ='шпоргалка-3'!B32 -> резерв | O32: ='шпоргалка-3'!C32 | P32: ='шпоргалка-3'!D32 | Q32: ='шпоргалка-3'!E32
A33: ='шпоргалка-1'!A33 -> 3 | B33: ='шпоргалка-1'!B33 -> #REF! | C33: ='шпоргалка-1'!C33 -> #REF! | D33: ='шпоргалка-1'!D33 -> #REF! | E33: ='шпоргалка-1'!E33 -> #REF! | G33: ='шпоргалка-2'!A33 -> 3 | H33: ='шпоргалка-2'!B33 -> резерв | I33: ='шпоргалка-2'!C33 | J33: ='шпоргалка-2'!D33 | K33: ='шпоргалка-2'!E33 | M33: ='шпоргалка-3'!A33 -> 3 | N33: ='шпоргалка-3'!B33 -> резерв | O33: ='шпоргалка-3'!C33 | P33: ='шпоргалка-3'!D33 | Q33: ='шпоргалка-3'!E33
A34: ='шпоргалка-1'!A34 -> 4 | B34: ='шпоргалка-1'!B34 -> #REF! | C34: ='шпоргалка-1'!C34 -> #REF! | D34: ='шпоргалка-1'!D34 -> #REF! | E34: ='шпоргалка-1'!E34 -> #REF! | G34: ='шпоргалка-2'!A34 -> 4 | H34: ='шпоргалка-2'!B34 -> резерв | I34: ='шпоргалка-2'!C34 | J34: ='шпоргалка-2'!D34 | K34: ='шпоргалка-2'!E34 | M34: ='шпоргалка-3'!A34 -> 4 | N34: ='шпоргалка-3'!B34 -> резерв | O34: ='шпоргалка-3'!C34 | P34: ='шпоргалка-3'!D34 | Q34: ='шпоргалка-3'!E34
A35: ='шпоргалка-1'!A35 -> 5 | B35: ='шпоргалка-1'!B35 -> #REF! | C35: ='шпоргалка-1'!C35 -> #REF! | D35: ='шпоргалка-1'!D35 -> #REF! | E35: ='шпоргалка-1'!E35 -> #REF! | G35: ='шпоргалка-2'!A35 -> 5 | H35: ='шпоргалка-2'!B35 -> резерв | I35: ='шпоргалка-2'!C35 | J35: ='шпоргалка-2'!D35 | K35: ='шпоргалка-2'!E35 | M35: ='шпоргалка-3'!A35 -> 5 | N35: ='шпоргалка-3'!B35 -> резерв | O35: ='шпоргалка-3'!C35 | P35: ='шпоргалка-3'!D35 | Q35: ='шпоргалка-3'!E35
A36: ='шпоргалка-1'!A36 -> 6 | B36: ='шпоргалка-1'!B36 -> #REF! | C36: ='шпоргалка-1'!C36 -> #REF! | D36: ='шпоргалка-1'!D36 -> #REF! | E36: ='шпоргалка-1'!E36 -> #REF! | G36: ='шпоргалка-2'!A36 -> 6 | H36: ='шпоргалка-2'!B36 -> резерв | I36: ='шпоргалка-2'!C36 | J36: ='шпоргалка-2'!D36 | K36: ='шпоргалка-2'!E36 | M36: ='шпоргалка-3'!A36 -> 6 | N36: ='шпоргалка-3'!B36 -> резерв | O36: ='шпоргалка-3'!C36 | P36: ='шпоргалка-3'!D36 | Q36: ='шпоргалка-3'!E36
A37: ='шпоргалка-1'!A37 -> 7 | B37: ='шпоргалка-1'!B37 -> #REF! | C37: ='шпоргалка-1'!C37 -> #REF! | D37: ='шпоргалка-1'!D37 -> #REF! | E37: ='шпоргалка-1'!E37 -> #REF! | G37: ='шпоргалка-2'!A37 -> 7 | H37: ='шпоргалка-2'!B37 -> резерв | I37: ='шпоргалка-2'!C37 | J37: ='шпоргалка-2'!D37 | K37: ='шпоргалка-2'!E37 | M37: ='шпоргалка-3'!A37 -> 7 | N37: ='шпоргалка-3'!B37 -> резерв | O37: ='шпоргалка-3'!C37 | P37: ='шпоргалка-3'!D37 | Q37: ='шпоргалка-3'!E37
A38: ='шпоргалка-1'!A38 -> 8 | B38: ='шпоргалка-1'!B38 -> #REF! | C38: ='шпоргалка-1'!C38 -> #REF! | D38: ='шпоргалка-1'!D38 -> #REF! | E38: ='шпоргалка-1'!E38 -> #REF! | G38: ='шпоргалка-2'!A38 -> 8 | H38: ='шпоргалка-2'!B38 -> резерв | I38: ='шпоргалка-2'!C38 | J38: ='шпоргалка-2'!D38 | K38: ='шпоргалка-2'!E38 | M38: ='шпоргалка-3'!A38 -> 8 | N38: ='шпоргалка-3'!B38 -> резерв | O38: ='шпоргалка-3'!C38 | P38: ='шпоргалка-3'!D38 | Q38: ='шпоргалка-3'!E38
B39: ='шпоргалка-1'!B39 -> SV004 - 5 | H39: ='шпоргалка-2'!B39 -> SV004 - 5 | N39: ='шпоргалка-3'!B39 -> SV004 - 5
A40: ='шпоргалка-1'!A40 -> 1 | B40: ='шпоргалка-1'!B40 -> #REF! | C40: ='шпоргалка-1'!C40 -> #REF! | D40: ='шпоргалка-1'!D40 -> #REF! | E40: ='шпоргалка-1'!E40 -> #REF! | G40: ='шпоргалка-2'!A40 -> 1 | H40: ='шпоргалка-2'!B40 -> резерв | I40: ='шпоргалка-2'!C40 | J40: ='шпоргалка-2'!D40 | K40: ='шпоргалка-2'!E40 | M40: ='шпоргалка-3'!A40 -> 1 | N40: ='шпоргалка-3'!B40 -> резерв | O40: ='шпоргалка-3'!C40 | P40: ='шпоргалка-3'!D40 | Q40: ='шпоргалка-3'!E40
A41: ='шпоргалка-1'!A41 -> 2 | B41: ='шпоргалка-1'!B41 -> #REF! | C41: ='шпоргалка-1'!C41 -> #REF! | D41: ='шпоргалка-1'!D41 -> #REF! | E41: ='шпоргалка-1'!E41 -> #REF! | G41: ='шпоргалка-2'!A41 -> 2 | H41: ='шпоргалка-2'!B41 -> резерв | I41: ='шпоргалка-2'!C41 | J41: ='шпоргалка-2'!D41 | K41: ='шпоргалка-2'!E41 | M41: ='шпоргалка-3'!A41 -> 2 | N41: ='шпоргалка-3'!B41 -> резерв | O41: ='шпоргалка-3'!C41 | P41: ='шпоргалка-3'!D41 | Q41: ='шпоргалка-3'!E41
...

Sheet Disp-1
B2: 1 | C2: =CONCATENATE("п.",'шпоргалка-1'!D4," - ",'шпоргалка-1'!B4) -> п. - резерв | D2: 1 | E2: =C2 -> п. - резерв | F2: 17 | G2: =CONCATENATE("п.",'шпоргалка-1'!D22," - ",'шпоргалка-1'!B22) -> #REF! | H2: 17 | I2: =G2 -> #REF! | K2: Display panel №1
B3: 2 | C3: =CONCATENATE("п.",'шпоргалка-1'!D5," - ",'шпоргалка-1'!B5) -> п. - резерв | D3: 2 | E3: =C3 -> п. - резерв | F3: 18 | G3: =CONCATENATE("п.",'шпоргалка-1'!D23," - ",'шпоргалка-1'!B23) -> #REF! | H3: 18 | I3: =G3 -> #REF!
B4: 3 | C4: =CONCATENATE("п.",'шпоргалка-1'!D6," - ",'шпоргалка-1'!B6) -> п. - резерв | D4: 3 | E4: =C4 -> п. - резерв | F4: 19 | G4: =CONCATENATE("п.",'шпоргалка-1'!D24," - ",'шпоргалка-1'!B24) -> #REF! | H4: 19 | I4: =G4 -> #REF!
B5: 4 | C5: =CONCATENATE("п.",'шпоргалка-1'!D7," - ",'шпоргалка-1'!B7) -> п. - резерв | D5: 4 | E5: =C5 -> п. - резерв | F5: 20 | G5: =CONCATENATE("п.",'шпоргалка-1'!D25," - ",'шпоргалка-1'!B25) -> #REF! | H5: 20 | I5: =G5 -> #REF!
B6: 5 | C6: =CONCATENATE("п.",'шпоргалка-1'!D8," - ",'шпоргалка-1'!B8) -> #REF! | D6: 5 | E6: =C6 -> #REF! | F6: 21 | G6: =CONCATENATE("п.",'шпоргалка-1'!D26," - ",'шпоргалка-1'!B26) -> #REF! | H6: 21 | I6: =G6 -> #REF!
B7: 6 | C7: =CONCATENATE("п.",'шпоргалка-1'!D9," - ",'шпоргалка-1'!B9) -> #REF! | D7: 6 | E7: =C7 -> #REF! | F7: 22 | G7: =CONCATENATE("п.",'шпоргалка-1'!D27," - ",'шпоргалка-1'!B27) -> #REF! | H7: 22 | I7: =G7 -> #REF!
B8: 7 | C8: =CONCATENATE("п.",'шпоргалка-1'!D10," - ",'шпоргалка-1'!B10) -> #REF! | D8: 7 | E8: =C8 -> #REF! | F8: 23 | G8: =CONCATENATE("п.",'шпоргалка-1'!D28," - ",'шпоргалка-1'!B28) -> #REF! | H8: 23 | I8: =G8 -> #REF!
B9: 8 | C9: =CONCATENATE("п.",'шпоргалка-1'!D11," - ",'шпоргалка-1'!B11) -> #REF! | D9: 8 | E9: =C9 -> #REF! | F9: 24 | G9: =CONCATENATE("п.",'шпоргалка-1'!D29," - ",'шпоргалка-1'!B29) -> #REF! | H9: 24 | I9: =G9 -> #REF!
B10: 9 | C10: =CONCATENATE("п.",'шпоргалка-1'!D13," - ",'шпоргалка-1'!B13) -> #REF! | D10: 9 | E10: =C10 -> #REF! | F10: 25 | G10: =CONCATENATE("п.",'шпоргалка-1'!D31," - ",'шпоргалка-1'!B31) -> #REF! | H10: 25 | I10: =G10 -> #REF!
B11: 10 | C11: =CONCATENATE("п.",'шпоргалка-1'!D14," - ",'шпоргалка-1'!B14) -> #REF! | D11: 10 | E11: =C11 -> #REF! | F11: 26 | G11: =CONCATENATE("п.",'шпоргалка-1'!D32," - ",'шпоргалка-1'!B32) -> #REF! | H11: 26 | I11: =G11 -> #REF!
B12: 11 | C12: =CONCATENATE("п.",'шпоргалка-1'!D15," - ",'шпоргалка-1'!B15) -> #REF! | D12: 11 | E12: =C12 -> #REF! | F12: 27 | G12: =CONCATENATE("п.",'шпоргалка-1'!D33," - ",'шпоргалка-1'!B33) -> #REF! | H12: 27 | I12: =G12 -> #REF!
B13: 12 | C13: =CONCATENATE("п.",'шпоргалка-1'!D16," - ",'шпоргалка-1'!B16) -> #REF! | D13: 12 | E13: =C13 -> #REF! | F13: 28 | G13: =CONCATENATE("п.",'шпоргалка-1'!D34," - ",'шпоргалка-1'!B34) -> #REF! | H13: 28 | I13: =G13 -> #REF!
B14: 13 | C14: =CONCATENATE("п.",'шпоргалка-1'!D17," - ",'шпоргалка-1'!B17) -> #REF! | D14: 13 | E14: =C14 -> #REF! | F14: 29 | G14: =CONCATENATE("п.",'шпоргалка-1'!D35," - ",'шпоргалка-1'!B35) -> #REF! | H14: 29 | I14: =G14 -> #REF!
B15: 14 | C15: =CONCATENATE("п.",'шпоргалка-1'!D18," - ",'шпоргалка-1'!B18) -> #REF! | D15: 14 | E15: =C15 -> #REF! | F15: 30 | G15: =CONCATENATE("п.",'шпоргалка-1'!D36," - ",'шпоргалка-1'!B36) -> #REF! | H15: 30 | I15: =G15 -> #REF!
B16: 15 | C16: =CONCATENATE("п.",'шпоргалка-1'!D19," - ",'шпоргалка-1'!B19) -> #REF! | D16: 15 | E16: =C16 -> #REF! | F16: 31 | G16: =CONCATENATE("п.",'шпоргалка-1'!D37," - ",'шпоргалка-1'!B37) -> #REF! | H16: 31 | I16: =G16 -> #REF!
B17: 16 | C17: =CONCATENATE("п.",'шпоргалка-1'!D20," - ",'шпоргалка-1'!B20) -> #REF! | D17: 16 | E17: =C17 -> #REF! | F17: 32 | G17: =CONCATENATE("п.",'шпоргалка-1'!D38," - ",'шпоргалка-1'!B38) -> #REF! | H17: 32 | I17: =G17 -> #REF!
B21: 33 | C21: =CONCATENATE("п.",'шпоргалка-1'!D40," - ",'шпоргалка-1'!B40) -> #REF! | D21: 33 | E21: =C21 -> #REF! | F21: 49 | G21: =CONCATENATE("п.",'шпоргалка-1'!D58," - ",'шпоргалка-1'!B58) -> #REF! | H21: 49 | I21: =G21 -> #REF! | K21: Display panel №2
B22: 34 | C22: =CONCATENATE("п.",'шпоргалка-1'!D41," - ",'шпоргалка-1'!B41) -> #REF! | D22: 34 | E22: =C22 -> #REF! | F22: 50 | G22: =CONCATENATE("п.",'шпоргалка-1'!D59," - ",'шпоргалка-1'!B59) -> #REF! | H22: 50 | I22: =G22 -> #REF!
B23: 35 | C23: =CONCATENATE("п.",'шпоргалка-1'!D42," - ",'шпоргалка-1'!B42) -> #REF! | D23: 35 | E23: =C23 -> #REF! | F23: 51 | G23: =CONCATENATE("п.",'шпоргалка-1'!D60," - ",'шпоргалка-1'!B60) -> #REF! | H23: 51 | I23: =G23 -> #REF!
B24: 36 | C24: =CONCATENATE("п.",'шпоргалка-1'!D43," - ",'шпоргалка-1'!B43) -> #REF! | D24: 36 | E24: =C24 -> #REF! | F24: 52 | G24: =CONCATENATE("п.",'шпоргалка-1'!D61," - ",'шпоргалка-1'!B61) -> #REF! | H24: 52 | I24: =G24 -> #REF!
B25: 37 | C25: =CONCATENATE("п.",'шпоргалка-1'!D44," - ",'шпоргалка-1'!B44) -> #REF! | D25: 37 | E25: =C25 -> #REF! | F25: 53 | G25: =CONCATENATE("п.",'шпоргалка-1'!D62," - ",'шпоргалка-1'!B62) -> #REF! | H25: 53 | I25: =G25 -> #REF!
B26: 38 | C26: =CONCATENATE("п.",'шпоргалка-1'!D45," - ",'шпоргалка-1'!B45) -> #REF! | D26: 38 | E26: =C26 -> #REF! | F26: 54 | G26: =CONCATENATE("п.",'шпоргалка-1'!D63," - ",'шпоргалка-1'!B63) -> #REF! | H26: 54 | I26: =G26 -> #REF!
B27: 39 | C27: =CONCATENATE("п.",'шпоргалка-1'!D46," - ",'шпоргалка-1'!B46) -> #REF! | D27: 39 | E27: =C27 -> #REF! | F27: 55 | G27: =CONCATENATE("п.",'шпоргалка-1'!D64," - ",'шпоргалка-1'!B64) -> #REF! | H27: 55 | I27: =G27 -> #REF!
B28: 40 | C28: =CONCATENATE("п.",'шпоргалка-1'!D47," - ",'шпоргалка-1'!B47) -> #REF! | D28: 40 | E28: =C28 -> #REF! | F28: 56 | G28: =CONCATENATE("п.",'шпоргалка-1'!D65," - ",'шпоргалка-1'!B65) -> #REF! | H28: 56 | I28: =G28 -> #REF!
B29: 41 | C29: =CONCATENATE("п.",'шпоргалка-1'!D49," - ",'шпоргалка-1'!B49) -> #REF! | D29: 41 | E29: =C29 -> #REF! | F29: 57 | G29: =CONCATENATE("п.",'шпоргалка-1'!D67," - ",'шпоргалка-1'!B67) -> #REF! | H29: 57 | I29: =G29 -> #REF!
B30: 42 | C30: =CONCATENATE("п.",'шпоргалка-1'!D50," - ",'шпоргалка-1'!B50) -> #REF! | D30: 42 | E30: =C30 -> #REF! | F30: 58 | G30: =CONCATENATE("п.",'шпоргалка-1'!D68," - ",'шпоргалка-1'!B68) -> #REF! | H30: 58 | I30: =G30 -> #REF!
B31: 43 | C31: =CONCATENATE("п.",'шпоргалка-1'!D51," - ",'шпоргалка-1'!B51) -> #REF! | D31: 43 | E31: =C31 -> #REF! | F31: 59 | G31: =CONCATENATE("п.",'шпоргалка-1'!D69," - ",'шпоргалка-1'!B69) -> #REF! | H31: 59 | I31: =G31 -> #REF!
B32: 44 | C32: =CONCATENATE("п.",'шпоргалка-1'!D52," - ",'шпоргалка-1'!B52) -> #REF! | D32: 44 | E32: =C32 -> #REF! | F32: 60 | G32: =CONCATENATE("п.",'шпоргалка-1'!D70," - ",'шпоргалка-1'!B70) -> #REF! | H32: 60 | I32: =G32 -> #REF!
B33: 45 | C33: =CONCATENATE("п.",'шпоргалка-1'!D53," - ",'шпоргалка-1'!B53) -> #REF! | D33: 45 | E33: =C33 -> #REF! | F33: 61 | G33: =CONCATENATE("п.",'шпоргалка-1'!D71," - ",'шпоргалка-1'!B71) -> #REF! | H33: 61 | I33: =G33 -> #REF!
B34: 46 | C34: =CONCATENATE("п.",'шпоргалка-1'!D54," - ",'шпоргалка-1'!B54) -> #REF! | D34: 46 | E34: =C34 -> #REF! | F34: 62 | G34: =CONCATENATE("п.",'шпоргалка-1'!D72," - ",'шпоргалка-1'!B72) -> #REF! | H34: 62 | I34: =G34 -> #REF!
B35: 47 | C35: =CONCATENATE("п.",'шпоргалка-1'!D55," - ",'шпоргалка-1'!B55) -> #REF! | D35: 47 | E35: =C35 -> #REF! | F35: 63 | G35: =CONCATENATE("п.",'шпоргалка-1'!D73," - ",'шпоргалка-1'!B73) -> #REF! | H35: 63 | I35: =G35 -> #REF!
B36: 48 | C36: =CONCATENATE("п.",'шпоргалка-1'!D56," - ",'шпоргалка-1'!B56) -> #REF! | D36: 48 | E36: =C36 -> #REF! | F36: 64 | G36: =CONCATENATE("п.",'шпоргалка-1'!D74," - ",'шпоргалка-1'!B74) -> #REF! | H36: 64 | I36: =G36 -> #REF!

Sheet Disp-2
B2: 1 | C2: =CONCATENATE("п.",'шпоргалка-2'!D4," - ",'шпоргалка-2'!B4) -> п. - резерв | D2: 1 | E2: =C2 -> п. - резерв | F2: 17 | G2: =CONCATENATE("п.",'шпоргалка-2'!D22," - ",'шпоргалка-2'!B22) -> п. - резерв | H2: 17 | I2: =G2 -> п. - резерв | K2: Display panel №1
